Workbook

Sheet Assumptions
A1: BBAI — DCF Model Assumptions
A2: All dollar inputs in $thousands | Blue = input | Black = formula | Yellow = key assumption
A4: A. HISTORICAL FINANCIAL DATA (Source: BBAI 10-K FY2025, filed 03/02/2026)
A5: Line Item | B5: FY2023 | C5: FY2024 | D5: FY2025 | E5: Notes
A6: Revenue | B6: 155164 | C6: 158236 | D6: 127672 | E6: Source: BBAI 10-K FY2025, p.94
A7: Cost of Revenue | B7: 114563 | C7: 113016 | D7: 99194 | E7: Source: BBAI 10-K FY2025, p.94
A8: Gross Profit | B8: =B6-B7 -> 40601 | C8: =C6-C7 -> 45220 | D8: =D6-D7 -> 28478 | E8: Formula: Revenue - CoR
A9: Gross Margin % | B9: =B8/B6 -> 0.26166508 | C9: =C8/C6 -> 0.28577568 | D9: =D8/D6 -> 0.22305596 | E9: Formula
A10: SG&A | B10: 71057 | C10: 80040 | D10: 95132 | E10: Source: BBAI 10-K FY2025, p.94
A11: R&D | B11: 5035 | C11: 10863 | D11: 16752 | E11: Source: BBAI 10-K FY2025, p.94
A12: EBIT (Operating Loss) | B12: -39034 | C12: -133420 | D12: -213897 | E12: Source: BBAI 10-K FY2025, p.94
A13: D&A | B13: 7901 | C13: 11873 | D13: 15281 | E13: Source: BBAI 10-K FY2025 Cash Flow, p.97
A14: Stock-Based Comp | B14: 18671 | C14: 21127 | D14: 23330 | E14: Source: BBAI 10-K FY2025 Cash Flow, p.97
A15: CapEx (PP&E) | B15: 2 | C15: 484 | D15: 525 | E15: Source: BBAI 10-K FY2025 Cash Flow, p.97
A16: Capitalized Software | B16: 3828 | C16: 10630 | D16: 3841 | E16: Source: BBAI 10-K FY2025 Cash Flow, p.97
A17: Interest Expense | B17: 24877 | C17: 25647 | D17: 18116 | E17: Source: BBAI 10-K FY2025, p.94
A18: Interest Income | B18: 392 | C18: 2293 | D18: 13253 | E18: Source: BBAI 10-K FY2025, p.94
A19: Net Loss | B19: -70657 | C19: -295547 | D19: -293914 | E19: Source: BBAI 10-K FY2025, p.94
A20: Adjusted EBITDA | C20: -2397 | D20: -35140 | E20: Source: BBAI Q4 2025 Press Release
A22: A2. BALANCE SHEET SNAPSHOT (Source: BBAI 10-K FY2025, p.93)
A23: Line Item | B23: FY2024 | C23: FY2025 | E23: Notes
A24: Cash & Equivalents | B24: 50141 | C24: 87126 | E24: Source: BBAI 10-K FY2025, p.93
A25: AFS Investments (Current) | B25: 0 | C25: 200461 | E25: Source: BBAI 10-K FY2025, p.93
A26: AFS Investments (Non-Current) | B26: 0 | C26: 173949 | E26: Source: BBAI 10-K FY2025, p.93
A27: Total Liquidity | B27: =B24+B25+B26 -> 50141 | C27: =C24+C25+C26 -> 461536 | E27: Formula: Cash + AFS Current + AFS Non-Current
A28: Accounts Receivable | B28: 38953 | C28: 22703 | E28: Source: BBAI 10-K FY2025, p.93
A29: Goodwill | B29: 119081 | C29: 241100 | E29: Source: BBAI 10-K FY2025, p.93
A30: Intangibles, net | B30: 119119 | C30: 139470 | E30: Source: BBAI 10-K FY2025, p.93
A31: Total Debt (Gross Principal) | B31: 200818 | C31: 142273 | E31: Source: BBAI 10-K FY2025, p.119 (2026 Notes $17,668 + 2029 Notes $124,605)
A32: Post-Jan-2026 Debt (2026 Notes Only) | C32: =C31-124605 -> 17668 | E32: Formula: 2029 Notes converted Jan 2026; only 2026 Notes ($17.7M) remain
A33: Shares Outstanding | B33: 251554378 | C33: 436955655 | E33: Source: BBAI 10-K FY2025, p.93
A34: Post-Jan-2026 Shares (est.) | C34: =C33+38100000 -> 475055655 | E34: Formula: FY25 shares + ~38.1M from 2029 Note conversions
A35: Federal NOL Carryforward | C35: 339600 | E35: Source: BBAI 10-K FY2025, p.125 (unlimited carryforward)
A38: B. REVENUE GROWTH ASSUMPTIONS (Yellow = key input to change per scenario)
A39: Assumption | B39: Base Case | C39: Bull Case | D39: Bear Case | E39: Notes
A40: FY2026 Revenue Growth Rate | B40: 0.17 | C40: 0.25 | D40: 0.05 | E40: Mgmt 2026 guide: $135M–$165M (~17% mid); Source: BBAI Q4 2025 Press Release
A41: FY2027 Revenue Growth Rate | B41: 0.2 | C41: 0.3 | D41: 0.1 | E41: Ask Sage ($229M acquisition) ramp + Middle East expansion
A42: FY2028 Revenue Growth Rate | B42: 0.22 | C42: 0.3 | D42: 0.12 | E42: Platform scaling; defense AI budget acceleration
A43: FY2029 Revenue Growth Rate | B43: 0.25 | C43: 0.3 | D43: 0.15 | E43: Continued DOGE-resilient contract wins
A44: FY2030 Revenue Growth Rate | B44: 0.22 | C44: 0.28 | D44: 0.12 | E44: TAM penetration in national security + travel/trade
...

Sheet DCF Model
A1: BBAI — 20-Year Unlevered Free Cash Flow DCF Model
A2: =IF(Assumptions!B50=1,"▶ ACTIVE: BASE CASE",IF(Assumptions!B50=2,"▶ ACTIVE: BULL CASE","▶ ACTIVE: BEAR CASE")) -> ▶ ACTIVE: BASE CASE
A3: Year | B3: FY2025 (Actual) | C3: 2026 | D3: 2027 | E3: 2028 | F3: 2029 | G3: 2030 | H3: 2031 | I3: 2032 | J3: 2033 | K3: 2034 | L3: 2035 | M3: 2036 | N3: 2037 | O3: 2038 | P3: 2039 | Q3: 2040 | R3: 2041 | S3: 2042 | T3: 2043 | U3: 2044 | V3: 2045
A4: A. REVENUE PROJECTION
A5: Revenue Growth Rate (Active Scenario) | B5: — | C5: =CHOOSE(Assumptions!B50,Assumptions!B40,Assumptions!C40,Assumptions!D40) -> 0.17 | D5: =CHOOSE(Assumptions!B50,Assumptions!B41,Assumptions!C41,Assumptions!D41) -> 0.2 | E5: =CHOOSE(Assumptions!B50,Assumptions!B42,Assumptions!C42,Assumptions!D42) -> 0.22 | F5: =CHOOSE(Assumptions!B50,Assumptions!B43,Assumptions!C43,Assumptions!D43) -> 0.25 | G5: =CHOOSE(Assumptions!B50,Assumptions!B44,Assumptions!C44,Assumptions!D44) -> 0.22 | H5: =CHOOSE(Assumptions!B50,Assumptions!B45,Assumptions!C45,Assumptions!D45) -> 0.18 | I5: =CHOOSE(Assumptions!B50,Assumptions!B45,Assumptions!C45,Assumptions!D45) -> 0.18 | J5: =CHOOSE(Assumptions!B50,Assumptions!B45,Assumptions!C45,Assumptions!D45) -> 0.18 | K5: =CHOOSE(Assumptions!B50,Assumptions!B45,Assumptions!C45,Assumptions!D45) -> 0.18 | L5: =CHOOSE(Assumptions!B50,Assumptions!B45,Assumptions!C45,Assumptions!D45) -> 0.18 | M5: =CHOOSE(Assumptions!B50,Assumptions!B46,Assumptions!C46,Assumptions!D46) -> 0.12 | N5: =CHOOSE(Assumptions!B50,Assumptions!B46,Assumptions!C46,Assumptions!D46) -> 0.12 | O5: =CHOOSE(Assumptions!B50,Assumptions!B46,Assumptions!C46,Assumptions!D46) -> 0.12 | P5: =CHOOSE(Assumptions!B50,Assumptions!B46,Assumptions!C46,Assumptions!D46) -> 0.12 | Q5: =CHOOSE(Assumptions!B50,Assumptions!B46,Assumptions!C46,Assumptions!D46) -> 0.12 | R5: =CHOOSE(Assumptions!B50,Assumptions!B47,Assumptions!C47,Assumptions!D47) -> 0.08 | S5: =CHOOSE(Assumptions!B50,Assumptions!B47,Assumptions!C47,Assumptions!D47) -> 0.08 | T5: =CHOOSE(Assumptions!B50,Assumptions!B47,Assumptions!C47,Assumptions!D47) -> 0.08 | U5: =CHOOSE(Assumptions!B50,Assumptions!B47,Assumptions!C47,Assumptions!D47) -> 0.08 | V5: =CHOOSE(Assumptions!B50,Assumptions!B47,Assumptions!C47,Assumptions!D47) -> 0.08
A6: Revenue ($000s) | B6: =Assumptions!D6 -> 127672 | C6: =B6*(1+C5) -> 149376.24 | D6: =C6*(1+D5) -> 179251.49 | E6: =D6*(1+E5) -> 218686.82 | F6: =E6*(1+F5) -> 273358.52 | G6: =F6*(1+G5) -> 333497.39 | H6: =G6*(1+H5) -> 393526.92 | I6: =H6*(1+I5) -> 464361.77 | J6: =I6*(1+J5) -> 547946.89 | ... V6: =U6*(1+V5) -> 1975656.2
A7: B. INCOME STATEMENT PROJECTION
A8: Gross Margin % | B8: =Assumptions!D9 -> 0.22305596 | C8: =CHOOSE(Assumptions!B50,Assumptions!B54,Assumptions!C54,Assumptions!D54) -> 0.24 | D8: =CHOOSE(Assumptions!B50,Assumptions!B55,Assumptions!C55,Assumptions!D55) -> 0.27 | E8: =CHOOSE(Assumptions!B50,Assumptions!B56,Assumptions!C56,Assumptions!D56) -> 0.3 | F8: =CHOOSE(Assumptions!B50,Assumptions!B57,Assumptions!C57,Assumptions!D57) -> 0.33 | G8: =CHOOSE(Assumptions!B50,Assumptions!B58,Assumptions!C58,Assumptions!D58) -> 0.35 | H8: =CHOOSE(Assumptions!B50,Assumptions!B59,Assumptions!C59,Assumptions!D59) -> 0.38 | I8: =CHOOSE(Assumptions!B50,Assumptions!B59,Assumptions!C59,Assumptions!D59) -> 0.38 | J8: =CHOOSE(Assumptions!B50,Assumptions!B59,Assumptions!C59,Assumptions!D59) -> 0.38 | K8: =CHOOSE(Assumptions!B50,Assumptions!B59,Assumptions!C59,Assumptions!D59) -> 0.38 | L8: =CHOOSE(Assumptions!B50,Assumptions!B59,Assumptions!C59,Assumptions!D59) -> 0.38 | M8: =CHOOSE(Assumptions!B50,Assumptions!B60,Assumptions!C60,Assumptions!D60) -> 0.42 | N8: =CHOOSE(Assumptions!B50,Assumptions!B60,Assumptions!C60,Assumptions!D60) -> 0.42 | O8: =CHOOSE(Assumptions!B50,Assumptions!B60,Assumptions!C60,Assumptions!D60) -> 0.42 | P8: =CHOOSE(Assumptions!B50,Assumptions!B60,Assumptions!C60,Assumptions!D60) -> 0.42 | Q8: =CHOOSE(Assumptions!B50,Assumptions!B60,Assumptions!C60,Assumptions!D60) -> 0.42 | R8: =CHOOSE(Assumptions!B50,Assumptions!B60,Assumptions!C60,Assumptions!D60) -> 0.42 | S8: =CHOOSE(Assumptions!B50,Assumptions!B60,Assumptions!C60,Assumptions!D60) -> 0.42 | T8: =CHOOSE(Assumptions!B50,Assumptions!B60,Assumptions!C60,Assumptions!D60) -> 0.42 | U8: =CHOOSE(Assumptions!B50,Assumptions!B60,Assumptions!C60,Assumptions!D60) -> 0.42 | V8: =CHOOSE(Assumptions!B50,Assumptions!B60,Assumptions!C60,Assumptions!D60) -> 0.42
A9: Gross Profit ($000s) | B9: =Assumptions!D8 -> 28478 | C9: =C6*C8 -> 35850.298 | D9: =D6*D8 -> 48397.902 | E9: =E6*E8 -> 65606.045 | F9: =F6*F8 -> 90208.311 | G9: =G6*G8 -> 116724.09 | H9: =H6*H8 -> 149540.23 | I9: =I6*I8 -> 176457.47 | J9: =J6*J8 -> 208219.82 | ... V9: =V6*V8 -> 829775.6
A10: SG&A as % Revenue | B10: =Assumptions!D10/Assumptions!D6 -> 0.74512814 | C10: =CHOOSE(Assumptions!B50,Assumptions!B61,Assumptions!C61,Assumptions!D61) -> 0.65 | D10: =CHOOSE(Assumptions!B50,Assumptions!B62,Assumptions!C62,Assumptions!D62) -> 0.55 | E10: =CHOOSE(Assumptions!B50,Assumptions!B63,Assumptions!C63,Assumptions!D63) -> 0.48 | F10: =CHOOSE(Assumptions!B50,Assumptions!B64,Assumptions!C64,Assumptions!D64) -> 0.42 | G10: =CHOOSE(Assumptions!B50,Assumptions!B65,Assumptions!C65,Assumptions!D65) -> 0.38 | H10: =CHOOSE(Assumptions!B50,Assumptions!B66,Assumptions!C66,Assumptions!D66) -> 0.3 | I10: =CHOOSE(Assumptions!B50,Assumptions!B66,Assumptions!C66,Assumptions!D66) -> 0.3 | J10: =CHOOSE(Assumptions!B50,Assumptions!B66,Assumptions!C66,Assumptions!D66) -> 0.3 | K10: =CHOOSE(Assumptions!B50,Assumptions!B66,Assumptions!C66,Assumptions!D66) -> 0.3 | L10: =CHOOSE(Assumptions!B50,Assumptions!B66,Assumptions!C66,Assumptions!D66) -> 0.3 | M10: =CHOOSE(Assumptions!B50,Assumptions!B67,Assumptions!C67,Assumptions!D67) -> 0.25 | N10: =CHOOSE(Assumptions!B50,Assumptions!B67,Assumptions!C67,Assumptions!D67) -> 0.25 | O10: =CHOOSE(Assumptions!B50,Assumptions!B67,Assumptions!C67,Assumptions!D67) -> 0.25 | P10: =CHOOSE(Assumptions!B50,Assumptions!B67,Assumptions!C67,Assumptions!D67) -> 0.25 | Q10: =CHOOSE(Assumptions!B50,Assumptions!B67,Assumptions!C67,Assumptions!D67) -> 0.25 | R10: =CHOOSE(Assumptions!B50,Assumptions!B67,Assumptions!C67,Assumptions!D67) -> 0.25 | S10: =CHOOSE(Assumptions!B50,Assumptions!B67,Assumptions!C67,Assumptions!D67) -> 0.25 | T10: =CHOOSE(Assumptions!B50,Assumptions!B67,Assumptions!C67,Assumptions!D67) -> 0.25 | U10: =CHOOSE(Assumptions!B50,Assumptions!B67,Assumptions!C67,Assumptions!D67) -> 0.25 | V10: =CHOOSE(Assumptions!B50,Assumptions!B67,Assumptions!C67,Assumptions!D67) -> 0.25
A11: SG&A ($000s) | B11: =Assumptions!D10 -> 95132 | C11: =C6*C10 -> 97094.556 | D11: =D6*D10 -> 98588.318 | E11: =E6*E10 -> 104969.67 | F11: =F6*F10 -> 114810.58 | G11: =G6*G10 -> 126729.01 | H11: =H6*H10 -> 118058.08 | I11: =I6*I10 -> 139308.53 | J11: =J6*J10 -> 164384.07 | ... V11: =V6*V10 -> 493914.05
A12: R&D as % Revenue | B12: =Assumptions!D11/Assumptions!D6 -> 0.13121123 | C12: =CHOOSE(Assumptions!B50,Assumptions!B68,Assumptions!C68,Assumptions!D68) -> 0.1 | D12: =CHOOSE(Assumptions!B50,Assumptions!B68,Assumptions!C68,Assumptions!D68) -> 0.1 | E12: =CHOOSE(Assumptions!B50,Assumptions!B68,Assumptions!C68,Assumptions!D68) -> 0.1 | F12: =CHOOSE(Assumptions!B50,Assumptions!B68,Assumptions!C68,Assumptions!D68) -> 0.1 | G12: =CHOOSE(Assumptions!B50,Assumptions!B68,Assumptions!C68,Assumptions!D68) -> 0.1 | H12: =CHOOSE(Assumptions!B50,Assumptions!B68,Assumptions!C68,Assumptions!D68) -> 0.1 | I12: =CHOOSE(Assumptions!B50,Assumptions!B68,Assumptions!C68,Assumptions!D68) -> 0.1 | J12: =CHOOSE(Assumptions!B50,Assumptions!B68,Assumptions!C68,Assumptions!D68) -> 0.1 | K12: =CHOOSE(Assumptions!B50,Assumptions!B68,Assumptions!C68,Assumptions!D68) -> 0.1 | L12: =CHOOSE(Assumptions!B50,Assumptions!B68,Assumptions!C68,Assumptions!D68) -> 0.1 | M12: =CHOOSE(Assumptions!B50,Assumptions!B68,Assumptions!C68,Assumptions!D68) -> 0.1 | N12: =CHOOSE(Assumptions!B50,Assumptions!B68,Assumptions!C68,Assumptions!D68) -> 0.1 | O12: =CHOOSE(Assumptions!B50,Assumptions!B68,Assumptions!C68,Assumptions!D68) -> 0.1 | P12: =CHOOSE(Assumptions!B50,Assumptions!B68,Assumptions!C68,Assumptions!D68) -> 0.1 | Q12: =CHOOSE(Assumptions!B50,Assumptions!B68,Assumptions!C68,Assumptions!D68) -> 0.1 | R12: =CHOOSE(Assumptions!B50,Assumptions!B68,Assumptions!C68,Assumptions!D68) -> 0.1 | S12: =CHOOSE(Assumptions!B50,Assumptions!B68,Assumptions!C68,Assumptions!D68) -> 0.1 | T12: =CHOOSE(Assumptions!B50,Assumptions!B68,Assumptions!C68,Assumptions!D68) -> 0.1 | U12: =CHOOSE(Assumptions!B50,Assumptions!B68,Assumptions!C68,Assumptions!D68) -> 0.1 | V12: =CHOOSE(Assumptions!B50,Assumptions!B68,Assumptions!C68,Assumptions!D68) -> 0.1
A13: R&D ($000s) | B13: =Assumptions!D11 -> 16752 | C13: =C6*C12 -> 14937.624 | D13: =D6*D12 -> 17925.149 | E13: =E6*E12 -> 21868.682 | F13: =F6*F12 -> 27335.852 | G13: =G6*G12 -> 33349.739 | H13: =H6*H12 -> 39352.692 | I13: =I6*I12 -> 46436.177 | J13: =J6*J12 -> 54794.689 | ... V13: =V6*V12 -> 197565.62
A14: EBIT ($000s) | B14: =Assumptions!D12 -> -213897 | C14: =C9-C11-C13 -> -76181.882 | D14: =D9-D11-D13 -> -68115.565 | E14: =E9-E11-E13 -> -61232.308 | F14: =F9-F11-F13 -> -51938.119 | G14: =G9-G11-G13 -> -43354.661 | H14: =H9-H11-H13 -> -7870.5385 | I14: =I9-I11-I13 -> -9287.2354 | J14: =J9-J11-J13 -> -10958.938 | ... V14: =V9-V11-V13 -> 138295.93
A15: EBIT Margin % | B15: =Assumptions!D12/Assumptions!D6 -> -1.6753634 | C15: =C14/C6 -> -0.51 | D15: =D14/D6 -> -0.38 | E15: =E14/E6 -> -0.28 | F15: =F14/F6 -> -0.19 | G15: =G14/G6 -> -0.13 | H15: =H14/H6 -> -0.02 | I15: =I14/I6 -> -0.02 | J15: =J14/J6 -> -0.02 | ... V15: =V14/V6 -> 0.07
A16: Cash Tax Rate (Active Scenario) | B16: =0 -> 0 | C16: =CHOOSE(Assumptions!B50,Assumptions!B73,Assumptions!C73,Assumptions!D73) -> 0 | D16: =CHOOSE(Assumptions!B50,Assumptions!B73,Assumptions!C73,Assumptions!D73) -> 0 | E16: =CHOOSE(Assumptions!B50,Assumptions!B73,Assumptions!C73,Assumptions!D73) -> 0 | F16: =CHOOSE(Assumptions!B50,Assumptions!B73,Assumptions!C73,Assumptions!D73) -> 0 | G16: =CHOOSE(Assumptions!B50,Assumptions!B73,Assumptions!C73,Assumptions!D73) -> 0 | H16: =CHOOSE(Assumptions!B50,Assumptions!B73,Assumptions!C73,Assumptions!D73) -> 0 | I16: =CHOOSE(Assumptions!B50,Assumptions!B73,Assumptions!C73,Assumptions!D73) -> 0 | J16: =CHOOSE(Assumptions!B50,Assumptions!B73,Assumptions!C73,Assumptions!D73) -> 0 | K16: =CHOOSE(Assumptions!B50,Assumptions!B73,Assumptions!C73,Assumptions!D73) -> 0 | L16: =CHOOSE(Assumptions!B50,Assumptions!B73,Assumptions!C73,Assumptions!D73) -> 0 | M16: =CHOOSE(Assumptions!B50,Assumptions!B73,Assumptions!C73,Assumptions!D73) -> 0 | N16: =CHOOSE(Assumptions!B50,Assumptions!B73,Assumptions!C73,Assumptions!D73) -> 0 | O16: =CHOOSE(Assumptions!B50,Assumptions!B73,Assumptions!C73,Assumptions!D73) -> 0 | P16: =CHOOSE(Assumptions!B50,Assumptions!B73,Assumptions!C73,Assumptions!D73) -> 0 | Q16: =CHOOSE(Assumptions!B50,Assumptions!B73,Assumptions!C73,Assumptions!D73) -> 0 | R16: =CHOOSE(Assumptions!B50,Assumptions!B73,Assumptions!C73,Assumptions!D73) -> 0 | S16: =CHOOSE(Assumptions!B50,Assumptions!B73,Assumptions!C73,Assumptions!D73) -> 0 | T16: =CHOOSE(Assumptions!B50,Assumptions!B73,Assumptions!C73,Assumptions!D73) -> 0 | U16: =CHOOSE(Assumptions!B50,Assumptions!B73,Assumptions!C73,Assumptions!D73) -> 0 | V16: =CHOOSE(Assumptions!B50,Assumptions!B73,Assumptions!C73,Assumptions!D73) -> 0
A17: NOPAT = EBIT × (1 − Tax Rate) ($000s) | B17: =B14*(1-B16) -> -213897 | C17: =C14*(1-C16) -> -76181.882 | D17: =D14*(1-D16) -> -68115.565 | E17: =E14*(1-E16) -> -61232.308 | F17: =F14*(1-F16) -> -51938.119 | G17: =G14*(1-G16) -> -43354.661 | H17: =H14*(1-H16) -> -7870.5385 | I17: =I14*(1-I16) -> -9287.2354 | ... V17: =V14*(1-V16) -> 138295.93
A18: C. UNLEVERED FREE CASH FLOW BUILD
A19: D&A as % Revenue | B19: =Assumptions!D13/Assumptions!D6 -> 0.11968952 | C19: =CHOOSE(Assumptions!B50,Assumptions!B69,Assumptions!C69,Assumptions!D69) -> 0.1 | D19: =CHOOSE(Assumptions!B50,Assumptions!B69,Assumptions!C69,Assumptions!D69) -> 0.1 | E19: =CHOOSE(Assumptions!B50,Assumptions!B69,Assumptions!C69,Assumptions!D69) -> 0.1 | F19: =CHOOSE(Assumptions!B50,Assumptions!B69,Assumptions!C69,Assumptions!D69) -> 0.1 | G19: =CHOOSE(Assumptions!B50,Assumptions!B69,Assumptions!C69,Assumptions!D69) -> 0.1 | H19: =CHOOSE(Assumptions!B50,Assumptions!B69,Assumptions!C69,Assumptions!D69) -> 0.1 | I19: =CHOOSE(Assumptions!B50,Assumptions!B69,Assumptions!C69,Assumptions!D69) -> 0.1 | J19: =CHOOSE(Assumptions!B50,Assumptions!B69,Assumptions!C69,Assumptions!D69) -> 0.1 | K19: =CHOOSE(Assumptions!B50,Assumptions!B69,Assumptions!C69,Assumptions!D69) -> 0.1 | L19: =CHOOSE(Assumptions!B50,Assumptions!B69,Assumptions!C69,Assumptions!D69) -> 0.1 | M19: =CHOOSE(Assumptions!B50,Assumptions!B69,Assumptions!C69,Assumptions!D69) -> 0.1 | N19: =CHOOSE(Assumptions!B50,Assumptions!B69,Assumptions!C69,Assumptions!D69) -> 0.1 | O19: =CHOOSE(Assumptions!B50,Assumptions!B69,Assumptions!C69,Assumptions!D69) -> 0.1 | P19: =CHOOSE(Assumptions!B50,Assumptions!B69,Assumptions!C69,Assumptions!D69) -> 0.1 | Q19: =CHOOSE(Assumptions!B50,Assumptions!B69,Assumptions!C69,Assumptions!D69) -> 0.1 | R19: =CHOOSE(Assumptions!B50,Assumptions!B69,Assumptions!C69,Assumptions!D69) -> 0.1 | S19: =CHOOSE(Assumptions!B50,Assumptions!B69,Assumptions!C69,Assumptions!D69) -> 0.1 | T19: =CHOOSE(Assumptions!B50,Assumptions!B69,Assumptions!C69,Assumptions!D69) -> 0.1 | U19: =CHOOSE(Assumptions!B50,Assumptions!B69,Assumptions!C69,Assumptions!D69) -> 0.1 | V19: =CHOOSE(Assumptions!B50,Assumptions!B69,Assumptions!C69,Assumptions!D69) -> 0.1
A20: (+) D&A ($000s) | B20: =Assumptions!D13 -> 15281 | C20: =C6*C19 -> 14937.624 | D20: =D6*D19 -> 17925.149 | E20: =E6*E19 -> 21868.682 | F20: =F6*F19 -> 27335.852 | G20: =G6*G19 -> 33349.739 | H20: =H6*H19 -> 39352.692 | I20: =I6*I19 -> 46436.177 | J20: =J6*J19 -> 54794.689 | ... V20: =V6*V19 -> 197565.62
A21: CapEx as % Revenue | B21: =(Assumptions!D15+Assumptions!D16)/Assumptions!D6 -> 0.034197005 | C21: =CHOOSE(Assumptions!B50,Assumptions!B70,Assumptions!C70,Assumptions!D70) -> 0.03 | D21: =CHOOSE(Assumptions!B50,Assumptions!B70,Assumptions!C70,Assumptions!D70) -> 0.03 | E21: =CHOOSE(Assumptions!B50,Assumptions!B70,Assumptions!C70,Assumptions!D70) -> 0.03 | F21: =CHOOSE(Assumptions!B50,Assumptions!B70,Assumptions!C70,Assumptions!D70) -> 0.03 | G21: =CHOOSE(Assumptions!B50,Assumptions!B70,Assumptions!C70,Assumptions!D70) -> 0.03 | H21: =CHOOSE(Assumptions!B50,Assumptions!B70,Assumptions!C70,Assumptions!D70) -> 0.03 | I21: =CHOOSE(Assumptions!B50,Assumptions!B70,Assumptions!C70,Assumptions!D70) -> 0.03 | J21: =CHOOSE(Assumptions!B50,Assumptions!B70,Assumptions!C70,Assumptions!D70) -> 0.03 | K21: =CHOOSE(Assumptions!B50,Assumptions!B70,Assumptions!C70,Assumptions!D70) -> 0.03 | L21: =CHOOSE(Assumptions!B50,Assumptions!B70,Assumptions!C70,Assumptions!D70) -> 0.03 | M21: =CHOOSE(Assumptions!B50,Assumptions!B70,Assumptions!C70,Assumptions!D70) -> 0.03 | N21: =CHOOSE(Assumptions!B50,Assumptions!B70,Assumptions!C70,Assumptions!D70) -> 0.03 | O21: =CHOOSE(Assumptions!B50,Assumptions!B70,Assumptions!C70,Assumptions!D70) -> 0.03 | P21: =CHOOSE(Assumptions!B50,Assumptions!B70,Assumptions!C70,Assumptions!D70) -> 0.03 | Q21: =CHOOSE(Assumptions!B50,Assumptions!B70,Assumptions!C70,Assumptions!D70) -> 0.03 | R21: =CHOOSE(Assumptions!B50,Assumptions!B70,Assumptions!C70,Assumptions!D70) -> 0.03 | S21: =CHOOSE(Assumptions!B50,Assumptions!B70,Assumptions!C70,Assumptions!D70) -> 0.03 | T21: =CHOOSE(Assumptions!B50,Assumptions!B70,Assumptions!C70,Assumptions!D70) -> 0.03 | U21: =CHOOSE(Assumptions!B50,Assumptions!B70,Assumptions!C70,Assumptions!D70) -> 0.03 | V21: =CHOOSE(Assumptions!B50,Assumptions!B70,Assumptions!C70,Assumptions!D70) -> 0.03
A22: (−) CapEx + Capitalized Software ($000s) | B22: =Assumptions!D15+Assumptions!D16 -> 4366 | C22: =C6*C21 -> 4481.2872 | D22: =D6*D21 -> 5377.5446 | E22: =E6*E21 -> 6560.6045 | F22: =F6*F21 -> 8200.7556 | G22: =G6*G21 -> 10004.922 | H22: =H6*H21 -> 11805.808 | I22: =I6*I21 -> 13930.853 | J22: =J6*J21 -> 16438.407 | ... V22: =V6*V21 -> 59269.686
A23: Δ NWC as % Revenue Change | B23: =0 -> 0 | C23: =CHOOSE(Assumptions!B50,Assumptions!B72,Assumptions!C72,Assumptions!D72) -> 0.05 | D23: =CHOOSE(Assumptions!B50,Assumptions!B72,Assumptions!C72,Assumptions!D72) -> 0.05 | E23: =CHOOSE(Assumptions!B50,Assumptions!B72,Assumptions!C72,Assumptions!D72) -> 0.05 | F23: =CHOOSE(Assumptions!B50,Assumptions!B72,Assumptions!C72,Assumptions!D72) -> 0.05 | G23: =CHOOSE(Assumptions!B50,Assumptions!B72,Assumptions!C72,Assumptions!D72) -> 0.05 | H23: =CHOOSE(Assumptions!B50,Assumptions!B72,Assumptions!C72,Assumptions!D72) -> 0.05 | I23: =CHOOSE(Assumptions!B50,Assumptions!B72,Assumptions!C72,Assumptions!D72) -> 0.05 | J23: =CHOOSE(Assumptions!B50,Assumptions!B72,Assumptions!C72,Assumptions!D72) -> 0.05 | K23: =CHOOSE(Assumptions!B50,Assumptions!B72,Assumptions!C72,Assumptions!D72) -> 0.05 | L23: =CHOOSE(Assumptions!B50,Assumptions!B72,Assumptions!C72,Assumptions!D72) -> 0.05 | M23: =CHOOSE(Assumptions!B50,Assumptions!B72,Assumptions!C72,Assumptions!D72) -> 0.05 | N23: =CHOOSE(Assumptions!B50,Assumptions!B72,Assumptions!C72,Assumptions!D72) -> 0.05 | O23: =CHOOSE(Assumptions!B50,Assumptions!B72,Assumptions!C72,Assumptions!D72) -> 0.05 | P23: =CHOOSE(Assumptions!B50,Assumptions!B72,Assumptions!C72,Assumptions!D72) -> 0.05 | Q23: =CHOOSE(Assumptions!B50,Assumptions!B72,Assumptions!C72,Assumptions!D72) -> 0.05 | R23: =CHOOSE(Assumptions!B50,Assumptions!B72,Assumptions!C72,Assumptions!D72) -> 0.05 | S23: =CHOOSE(Assumptions!B50,Assumptions!B72,Assumptions!C72,Assumptions!D72) -> 0.05 | T23: =CHOOSE(Assumptions!B50,Assumptions!B72,Assumptions!C72,Assumptions!D72) -> 0.05 | U23: =CHOOSE(Assumptions!B50,Assumptions!B72,Assumptions!C72,Assumptions!D72) -> 0.05 | V23: =CHOOSE(Assumptions!B50,Assumptions!B72,Assumptions!C72,Assumptions!D72) -> 0.05
A24: (−) Change in NWC ($000s) | B24: =0 -> 0 | C24: =(C6-B6)*C23 -> 1085.212 | D24: =(D6-C6)*D23 -> 1493.7624 | E24: =(E6-D6)*E23 -> 1971.7664 | F24: =(F6-E6)*F23 -> 2733.5852 | G24: =(G6-F6)*G23 -> 3006.9437 | H24: =(H6-G6)*H23 -> 3001.4765 | I24: =(I6-H6)*I23 -> 3541.7423 | J24: =(J6-I6)*J23 -> 4179.2559 | ... V24: =(V6-U6)*V23 -> 7317.2452
A25: UNLEVERED FCF ($000s) | B25: =B17+B20-B22-B24 -> -202982 | C25: =C17+C20-C22-C24 -> -66810.758 | D25: =D17+D20-D22-D24 -> -57061.724 | E25: =E17+E20-E22-E24 -> -47895.998 | F25: =F17+F20-F22-F24 -> -35536.607 | G25: =G17+G20-G22-G24 -> -23016.787 | H25: =H17+H20-H22-H24 -> 16674.87 | I25: =I17+I20-I22-I24 -> 19676.346 | ... V25: =V17+V20-V22-V24 -> 269274.62
A26: UFCF Margin % | B26: =IF(B6<>0,B25/B6,0) -> -1.5898709 | C26: =IF(C6<>0,C25/C6,0) -> -0.44726496 | D26: =IF(D6<>0,D25/D6,0) -> -0.31833333 | E26: =IF(E6<>0,E25/E6,0) -> -0.21901639 | F26: =IF(F6<>0,F25/F6,0) -> -0.13 | G26: =IF(G6<>0,G25/G6,0) -> -0.069016393 | H26: =IF(H6<>0,H25/H6,0) -> 0.042372881 | I26: =IF(I6<>0,I25/I6,0) -> 0.042372881 | ... V26: =IF(V6<>0,V25/V6,0) -> 0.1362963
A27: D. DISCOUNTING (Mid-Year Convention)
A28: WACC (Active Scenario) | B28: =CHOOSE(Assumptions!B50,Assumptions!B87,Assumptions!C87,Assumptions!D87) -> 0.17201 | C28: =CHOOSE(Assumptions!B50,Assumptions!B87,Assumptions!C87,Assumptions!D87) -> 0.17201 | D28: =CHOOSE(Assumptions!B50,Assumptions!B87,Assumptions!C87,Assumptions!D87) -> 0.17201 | E28: =CHOOSE(Assumptions!B50,Assumptions!B87,Assumptions!C87,Assumptions!D87) -> 0.17201 | F28: =CHOOSE(Assumptions!B50,Assumptions!B87,Assumptions!C87,Assumptions!D87) -> 0.17201 | G28: =CHOOSE(Assumptions!B50,Assumptions!B87,Assumptions!C87,Assumptions!D87) -> 0.17201 | H28: =CHOOSE(Assumptions!B50,Assumptions!B87,Assumptions!C87,Assumptions!D87) -> 0.17201 | I28: =CHOOSE(Assumptions!B50,Assumptions!B87,Assumptions!C87,Assumptions!D87) -> 0.17201 | J28: =CHOOSE(Assumptions!B50,Assumptions!B87,Assumptions!C87,Assumptions!D87) -> 0.17201 | K28: =CHOOSE(Assumptions!B50,Assumptions!B87,Assumptions!C87,Assumptions!D87) -> 0.17201 | L28: =CHOOSE(Assumptions!B50,Assumptions!B87,Assumptions!C87,Assumptions!D87) -> 0.17201 | M28: =CHOOSE(Assumptions!B50,Assumptions!B87,Assumptions!C87,Assumptions!D87) -> 0.17201 | N28: =CHOOSE(Assumptions!B50,Assumptions!B87,Assumptions!C87,Assumptions!D87) -> 0.17201 | O28: =CHOOSE(Assumptions!B50,Assumptions!B87,Assumptions!C87,Assumptions!D87) -> 0.17201 | P28: =CHOOSE(Assumptions!B50,Assumptions!B87,Assumptions!C87,Assumptions!D87) -> 0.17201 | Q28: =CHOOSE(Assumptions!B50,Assumptions!B87,Assumptions!C87,Assumptions!D87) -> 0.17201 | R28: =CHOOSE(Assumptions!B50,Assumptions!B87,Assumptions!C87,Assumptions!D87) -> 0.17201 | S28: =CHOOSE(Assumptions!B50,Assumptions!B87,Assumptions!C87,Assumptions!D87) -> 0.17201 | T28: =CHOOSE(Assumptions!B50,Assumptions!B87,Assumptions!C87,Assumptions!D87) -> 0.17201 | U28: =CHOOSE(Assumptions!B50,Assumptions!B87,Assumptions!C87,Assumptions!D87) -> 0.17201 | V28: =CHOOSE(Assumptions!B50,Assumptions!B87,Assumptions!C87,Assumptions!D87) -> 0.17201
A29: Discount Period (Mid-Year) | B29: — | C29: =1-0.5 -> 0.5 | D29: =2-0.5 -> 1.5 | E29: =3-0.5 -> 2.5 | F29: =4-0.5 -> 3.5 | G29: =5-0.5 -> 4.5 | H29: =6-0.5 -> 5.5 | I29: =7-0.5 -> 6.5 | J29: =8-0.5 -> 7.5 | K29: =9-0.5 -> 8.5 | L29: =10-0.5 -> 9.5 | M29: =11-0.5 -> 10.5 | N29: =12-0.5 -> 11.5 | O29: =13-0.5 -> 12.5 | P29: =14-0.5 -> 13.5 | Q29: =15-0.5 -> 14.5 | R29: =16-0.5 -> 15.5 | S29: =17-0.5 -> 16.5 | T29: =18-0.5 -> 17.5 | U29: =19-0.5 -> 18.5 | V29: =20-0.5 -> 19.5
A30: Discount Factor | B30: — | C30: =1/(1+C28)^C29 -> 0.92370723 | D30: =1/(1+D28)^D29 -> 0.78813937 | E30: =1/(1+E28)^E29 -> 0.67246813 | F30: =1/(1+F28)^F29 -> 0.57377337 | G30: =1/(1+G28)^G29 -> 0.48956355 | H30: =1/(1+H28)^H29 -> 0.41771277 | I30: =1/(1+I28)^I29 -> 0.35640717 | J30: =1/(1+J28)^J29 -> 0.30409909 | ... V30: =1/(1+V28)^V29 -> 0.045273004
A31: PV of UFCF ($000s) | B31: — | C31: =C25*C30 -> -61713.58 | D31: =D25*D30 -> -44972.591 | E31: =E25*E30 -> -32208.532 | F31: =F25*F30 -> -20389.959 | G31: =G25*G30 -> -11268.18 | H31: =H25*H30 -> 6965.306 | I31: =I25*I30 -> 7012.791 | J31: =J25*J30 -> 7060.5996 | ... V31: =V25*V30 -> 12190.871
A32: Sum of PV (UFCF) — Years 1–20 ($000s) | B32: =SUM(C31:V31) -> 36455.635
A33: E. TERMINAL VALUE (Gordon Growth Model — Primary)
A34: Year 20 UFCF ($000s) | B34: =V25 -> 269274.62
A35: Terminal Growth Rate (Active Scenario) | B35: =CHOOSE(Assumptions!B50,Assumptions!B92,Assumptions!C92,Assumptions!D92) -> 0.03
A36: WACC (Active Scenario) | B36: =CHOOSE(Assumptions!B50,Assumptions!B87,Assumptions!C87,Assumptions!D87) -> 0.17201
A37: Terminal Value (undiscounted) ($000s) | B37: =B34*(1+B35)/(B36-B35) -> 1953051.6
A38: Terminal Value Discount Factor (Year 20) | B38: =1/(1+V28)^20 -> 0.041819001
A39: PV of Terminal Value ($000s) | B39: =B37*B38 -> 81674.668
A40: Terminal Value as % of Total Enterprise Value | B40: =B39/(B32+B39) -> 0.69139472
...

Sheet Revenue Bridge
A1: BBAI — Revenue Bridge & Growth Schedule
A2: Metric | B2: 2026 | C2: 2027 | D2: 2028 | E2: 2029 | F2: 2030 | G2: 2031 | H2: 2032 | I2: 2033 | J2: 2034 | K2: 2035 | L2: 2036 | M2: 2037 | N2: 2038 | O2: 2039 | P2: 2040 | Q2: 2041 | R2: 2042 | S2: 2043 | T2: 2044 | U2: 2045
A3: Revenue ($000s) | B3: ='DCF Model'!C6 -> 149376.24 | C3: ='DCF Model'!D6 -> 179251.49 | D3: ='DCF Model'!E6 -> 218686.82 | E3: ='DCF Model'!F6 -> 273358.52 | F3: ='DCF Model'!G6 -> 333497.39 | G3: ='DCF Model'!H6 -> 393526.92 | H3: ='DCF Model'!I6 -> 464361.77 | I3: ='DCF Model'!J6 -> 547946.89 | ... U3: ='DCF Model'!V6 -> 1975656.2
A4: YoY $ Change | B4: ='DCF Model'!C6-'DCF Model'!B6 -> 21704.24 | C4: ='DCF Model'!D6-'DCF Model'!C6 -> 29875.248 | D4: ='DCF Model'!E6-'DCF Model'!D6 -> 39435.327 | E4: ='DCF Model'!F6-'DCF Model'!E6 -> 54671.704 | F4: ='DCF Model'!G6-'DCF Model'!F6 -> 60138.874 | G4: ='DCF Model'!H6-'DCF Model'!G6 -> 60029.531 | H4: ='DCF Model'!I6-'DCF Model'!H6 -> 70834.846 | I4: ='DCF Model'!J6-'DCF Model'!I6 -> 83585.119 | ... U4: ='DCF Model'!V6-'DCF Model'!U6 -> 146344.9
A5: YoY Growth % | B5: ='DCF Model'!C5 -> 0.17 | C5: ='DCF Model'!D5 -> 0.2 | D5: ='DCF Model'!E5 -> 0.22 | E5: ='DCF Model'!F5 -> 0.25 | F5: ='DCF Model'!G5 -> 0.22 | G5: ='DCF Model'!H5 -> 0.18 | H5: ='DCF Model'!I5 -> 0.18 | I5: ='DCF Model'!J5 -> 0.18 | ... U5: ='DCF Model'!V5 -> 0.08
A6: Gross Profit ($000s) | B6: ='DCF Model'!C9 -> 35850.298 | C6: ='DCF Model'!D9 -> 48397.902 | D6: ='DCF Model'!E9 -> 65606.045 | E6: ='DCF Model'!F9 -> 90208.311 | F6: ='DCF Model'!G9 -> 116724.09 | G6: ='DCF Model'!H9 -> 149540.23 | H6: ='DCF Model'!I9 -> 176457.47 | I6: ='DCF Model'!J9 -> 208219.82 | ... U6: ='DCF Model'!V9 -> 829775.6
A7: Gross Margin % | B7: ='DCF Model'!C8 -> 0.24 | C7: ='DCF Model'!D8 -> 0.27 | D7: ='DCF Model'!E8 -> 0.3 | E7: ='DCF Model'!F8 -> 0.33 | F7: ='DCF Model'!G8 -> 0.35 | G7: ='DCF Model'!H8 -> 0.38 | H7: ='DCF Model'!I8 -> 0.38 | I7: ='DCF Model'!J8 -> 0.38 | ... U7: ='DCF Model'!V8 -> 0.42
A8: SG&A ($000s) | B8: ='DCF Model'!C11 -> 97094.556 | C8: ='DCF Model'!D11 -> 98588.318 | D8: ='DCF Model'!E11 -> 104969.67 | E8: ='DCF Model'!F11 -> 114810.58 | F8: ='DCF Model'!G11 -> 126729.01 | G8: ='DCF Model'!H11 -> 118058.08 | H8: ='DCF Model'!I11 -> 139308.53 | I8: ='DCF Model'!J11 -> 164384.07 | ... U8: ='DCF Model'!V11 -> 493914.05
A9: R&D ($000s) | B9: ='DCF Model'!C13 -> 14937.624 | C9: ='DCF Model'!D13 -> 17925.149 | D9: ='DCF Model'!E13 -> 21868.682 | E9: ='DCF Model'!F13 -> 27335.852 | F9: ='DCF Model'!G13 -> 33349.739 | G9: ='DCF Model'!H13 -> 39352.692 | H9: ='DCF Model'!I13 -> 46436.177 | I9: ='DCF Model'!J13 -> 54794.689 | ... U9: ='DCF Model'!V13 -> 197565.62
A10: EBIT ($000s) | B10: ='DCF Model'!C14 -> -76181.882 | C10: ='DCF Model'!D14 -> -68115.565 | D10: ='DCF Model'!E14 -> -61232.308 | E10: ='DCF Model'!F14 -> -51938.119 | F10: ='DCF Model'!G14 -> -43354.661 | G10: ='DCF Model'!H14 -> -7870.5385 | H10: ='DCF Model'!I14 -> -9287.2354 | I10: ='DCF Model'!J14 -> -10958.938 | ... U10: ='DCF Model'!V14 -> 138295.93
A11: EBIT Margin % | B11: ='DCF Model'!C15 -> -0.51 | C11: ='DCF Model'!D15 -> -0.38 | D11: ='DCF Model'!E15 -> -0.28 | E11: ='DCF Model'!F15 -> -0.19 | F11: ='DCF Model'!G15 -> -0.13 | G11: ='DCF Model'!H15 -> -0.02 | H11: ='DCF Model'!I15 -> -0.02 | I11: ='DCF Model'!J15 -> -0.02 | ... U11: ='DCF Model'!V15 -> 0.07
A12: NOPAT ($000s) | B12: ='DCF Model'!C17 -> -76181.882 | C12: ='DCF Model'!D17 -> -68115.565 | D12: ='DCF Model'!E17 -> -61232.308 | E12: ='DCF Model'!F17 -> -51938.119 | F12: ='DCF Model'!G17 -> -43354.661 | G12: ='DCF Model'!H17 -> -7870.5385 | H12: ='DCF Model'!I17 -> -9287.2354 | I12: ='DCF Model'!J17 -> -10958.938 | ... U12: ='DCF Model'!V17 -> 138295.93
A13: D&A ($000s) | B13: ='DCF Model'!C20 -> 14937.624 | C13: ='DCF Model'!D20 -> 17925.149 | D13: ='DCF Model'!E20 -> 21868.682 | E13: ='DCF Model'!F20 -> 27335.852 | F13: ='DCF Model'!G20 -> 33349.739 | G13: ='DCF Model'!H20 -> 39352.692 | H13: ='DCF Model'!I20 -> 46436.177 | I13: ='DCF Model'!J20 -> 54794.689 | ... U13: ='DCF Model'!V20 -> 197565.62
A14: CapEx ($000s) | B14: ='DCF Model'!C22 -> 4481.2872 | C14: ='DCF Model'!D22 -> 5377.5446 | D14: ='DCF Model'!E22 -> 6560.6045 | E14: ='DCF Model'!F22 -> 8200.7556 | F14: ='DCF Model'!G22 -> 10004.922 | G14: ='DCF Model'!H22 -> 11805.808 | H14: ='DCF Model'!I22 -> 13930.853 | I14: ='DCF Model'!J22 -> 16438.407 | ... U14: ='DCF Model'!V22 -> 59269.686
A15: Δ NWC ($000s) | B15: ='DCF Model'!C24 -> 1085.212 | C15: ='DCF Model'!D24 -> 1493.7624 | D15: ='DCF Model'!E24 -> 1971.7664 | E15: ='DCF Model'!F24 -> 2733.5852 | F15: ='DCF Model'!G24 -> 3006.9437 | G15: ='DCF Model'!H24 -> 3001.4765 | H15: ='DCF Model'!I24 -> 3541.7423 | I15: ='DCF Model'!J24 -> 4179.2559 | ... U15: ='DCF Model'!V24 -> 7317.2452
A16: UFCF ($000s) | B16: ='DCF Model'!C25 -> -66810.758 | C16: ='DCF Model'!D25 -> -57061.724 | D16: ='DCF Model'!E25 -> -47895.998 | E16: ='DCF Model'!F25 -> -35536.607 | F16: ='DCF Model'!G25 -> -23016.787 | G16: ='DCF Model'!H25 -> 16674.87 | H16: ='DCF Model'!I25 -> 19676.346 | I16: ='DCF Model'!J25 -> 23218.089 | ... U16: ='DCF Model'!V25 -> 269274.62
A17: UFCF Margin % | B17: ='DCF Model'!C26 -> -0.44726496 | C17: ='DCF Model'!D26 -> -0.31833333 | D17: ='DCF Model'!E26 -> -0.21901639 | E17: ='DCF Model'!F26 -> -0.13 | F17: ='DCF Model'!G26 -> -0.069016393 | G17: ='DCF Model'!H26 -> 0.042372881 | H17: ='DCF Model'!I26 -> 0.042372881 | I17: ='DCF Model'!J26 -> 0.042372881 | ... U17: ='DCF Model'!V26 -> 0.1362963
A18: PV of UFCF ($000s) | B18: ='DCF Model'!C31 -> -61713.58 | C18: ='DCF Model'!D31 -> -44972.591 | D18: ='DCF Model'!E31 -> -32208.532 | E18: ='DCF Model'!F31 -> -20389.959 | F18: ='DCF Model'!G31 -> -11268.18 | G18: ='DCF Model'!H31 -> 6965.306 | H18: ='DCF Model'!I31 -> 7012.791 | I18: ='DCF Model'!J31 -> 7060.5996 | ... U18: ='DCF Model'!V31 -> 12190.871

Sheet $10 Re-Rating Scenario
A1: BBAI — $10 Re-Rating Scenario | "Proven AI Platform" Path to Value
A2: THESIS: BBAI achieves SaaS-like gross margins (60%+) by 2036 as Ask Sage platform scales, cuts SG&A to 20% via operational leverage, turns FCF-positive by 2028, and earns a WACC re-rating to 10% as it de-risks (debt-free, profitable, defense-AI category leader). Net cash of $444M provides ~$0.93/share floor regardless of DCF.
A3: Year | B3: FY2025 (Actual) | C3: 2026 | D3: 2027 | E3: 2028 | F3: 2029 | G3: 2030 | H3: 2031 | I3: 2032 | J3: 2033 | K3: 2034 | L3: 2035 | M3: 2036 | N3: 2037 | O3: 2038 | P3: 2039 | Q3: 2040 | R3: 2041 | S3: 2042 | T3: 2043 | U3: 2044 | V3: 2045
A4: A. REVENUE PROJECTION (Same growth rates as Base Case — value comes from margin & WACC, not revenue heroics)
A5: Revenue Growth Rate | B5: — | C5: =B202 -> 0.17 | D5: =B203 -> 0.22 | E5: =B204 -> 0.25 | F5: =B205 -> 0.28 | G5: =B206 -> 0.25 | H5: =B207 -> 0.2 | I5: =B207 -> 0.2 | J5: =B207 -> 0.2 | K5: =B207 -> 0.2 | L5: =B207 -> 0.2 | M5: =B208 -> 0.14 | N5: =B208 -> 0.14 | O5: =B208 -> 0.14 | P5: =B208 -> 0.14 | Q5: =B208 -> 0.14 | R5: =B209 -> 0.1 | S5: =B209 -> 0.1 | T5: =B209 -> 0.1 | U5: =B209 -> 0.1 | V5: =B209 -> 0.1
A6: Revenue ($000s) | B6: =Assumptions!D6 -> 127672 | C6: =B6*(1+C5) -> 149376.24 | D6: =C6*(1+D5) -> 182239.01 | E6: =D6*(1+E5) -> 227798.77 | F6: =E6*(1+F5) -> 291582.42 | G6: =F6*(1+G5) -> 364478.03 | H6: =G6*(1+H5) -> 437373.63 | I6: =H6*(1+I5) -> 524848.36 | J6: =I6*(1+J5) -> 629818.03 | ... V6: =U6*(1+V5) -> 2812323.4
A7: B. P&L — KEY DIFFERENCE: Faster gross margin ramp + aggressive SG&A normalization vs Base Case
A8: Gross Margin % ← KEY LEVER | B8: =Assumptions!D15 -> 525 | C8: =B210 -> 0.28 | D8: =B211 -> 0.33 | E8: =B212 -> 0.38 | F8: =B213 -> 0.43 | G8: =B214 -> 0.47 | H8: =B215 -> 0.51 | I8: =B215 -> 0.51 | J8: =B215 -> 0.51 | K8: =B215 -> 0.51 | L8: =B215 -> 0.51 | M8: =B216 -> 0.6 | N8: =B216 -> 0.6 | O8: =B216 -> 0.6 | P8: =B216 -> 0.6 | Q8: =B216 -> 0.6 | R8: =B216 -> 0.6 | S8: =B216 -> 0.6 | T8: =B216 -> 0.6 | U8: =B216 -> 0.6 | V8: =B216 -> 0.6
A9: Gross Profit ($000s) | B9: =B6*B8 -> 67027800 | C9: =C6*C8 -> 41825.347 | D9: =D6*D8 -> 60138.874 | E9: =E6*E8 -> 86563.531 | F9: =F6*F8 -> 125380.44 | G9: =G6*G8 -> 171304.67 | H9: =H6*H8 -> 223060.55 | I9: =I6*I8 -> 267672.66 | ... V9: =V6*V8 -> 1687394
A10: SG&A as % Revenue ← KEY LEVER | B10: =Assumptions!D12/Assumptions!D6 -> -1.6753634 | C10: =B217 -> 0.52 | D10: =B218 -> 0.42 | E10: =B219 -> 0.34 | F10: =B220 -> 0.28 | G10: =B221 -> 0.24 | H10: =B222 -> 0.22 | I10: =B222 -> 0.22 | J10: =B222 -> 0.22 | K10: =B222 -> 0.22 | L10: =B222 -> 0.22 | M10: =B223 -> 0.2 | N10: =B223 -> 0.2 | O10: =B223 -> 0.2 | P10: =B223 -> 0.2 | Q10: =B223 -> 0.2 | R10: =B223 -> 0.2 | S10: =B223 -> 0.2 | T10: =B223 -> 0.2 | U10: =B223 -> 0.2 | V10: =B223 -> 0.2
A11: SG&A ($000s) | B11: =B6*B10 -> -213897 | C11: =C6*C10 -> 77675.645 | D11: =D6*D10 -> 76540.385 | E11: =E6*E10 -> 77451.58 | F11: =F6*F10 -> 81643.078 | G11: =G6*G10 -> 87474.726 | H11: =H6*H10 -> 96222.199 | I11: =I6*I10 -> 115466.64 | ... V11: =V6*V10 -> 562464.68
A12: R&D as % Revenue | C12: =B224 -> 0.1 | D12: =B224 -> 0.1 | E12: =B224 -> 0.1 | F12: =B224 -> 0.1 | G12: =B224 -> 0.1 | H12: =B224 -> 0.1 | I12: =B224 -> 0.1 | J12: =B224 -> 0.1 | K12: =B224 -> 0.1 | L12: =B224 -> 0.1 | M12: =B224 -> 0.1 | N12: =B224 -> 0.1 | O12: =B224 -> 0.1 | P12: =B224 -> 0.1 | Q12: =B224 -> 0.1 | R12: =B224 -> 0.1 | S12: =B224 -> 0.1 | T12: =B224 -> 0.1 | U12: =B224 -> 0.1 | V12: =B224 -> 0.1
A13: EBIT ($000s) | B13: =B9-B11-B6*Assumptions!B68 -> 67228930 | C13: =C9-C11-C6*B224 -> -50787.922 | D13: =D9-D11-D6*B224 -> -34625.412 | E13: =E9-E11-E6*B224 -> -13667.926 | F13: =F9-F11-F6*B224 -> 14579.121 | G13: =G9-G11-G6*B224 -> 47382.143 | H13: =H9-H11-H6*B224 -> 83100.99 | I13: =I9-I11-I6*B224 -> 99721.188 | J13: =J9-J11-J6*B224 -> 119665.43 | K13: =K9-K11-K6*B224 -> 143598.51 | L13: =L9-L11-L6*B224 -> 172318.21 | M13: =M9-M11-M6*B224 -> 310172.78 | N13: =N9-N11-N6*B224 -> 353596.97 | O13: =O9-O11-O6*B224 -> 403100.55 | P13: =P9-P11-P6*B224 -> 459534.62 | Q13: =Q9-Q11-Q6*B224 -> 523869.47 | R13: =R9-R11-R6*B224 -> 576256.42 | S13: =S9-S11-S6*B224 -> 633882.06 | T13: =T9-T11-T6*B224 -> 697270.27 | U13: =U9-U11-U6*B224 -> 766997.29 | V13: =V9-V11-V6*B224 -> 843697.02
A14: EBIT Margin % | B14: =IF(B6<>0,B13/B6,0) -> 526.57536 | C14: =IF(C6<>0,C13/C6,0) -> -0.34 | D14: =IF(D6<>0,D13/D6,0) -> -0.19 | E14: =IF(E6<>0,E13/E6,0) -> -0.06 | F14: =IF(F6<>0,F13/F6,0) -> 0.05 | G14: =IF(G6<>0,G13/G6,0) -> 0.13 | H14: =IF(H6<>0,H13/H6,0) -> 0.19 | I14: =IF(I6<>0,I13/I6,0) -> 0.19 | ... V14: =IF(V6<>0,V13/V6,0) -> 0.3
A15: NOPAT ($000s) | B15: =B13*(1-B228) -> 67228930 | C15: =C13*(1-B228) -> -50787.922 | D15: =D13*(1-B228) -> -34625.412 | E15: =E13*(1-B228) -> -13667.926 | F15: =F13*(1-B228) -> 14579.121 | G15: =G13*(1-B228) -> 47382.143 | H15: =H13*(1-B228) -> 83100.99 | I15: =I13*(1-B228) -> 99721.188 | J15: =J13*(1-B228) -> 119665.43 | K15: =K13*(1-B228) -> 143598.51 | L15: =L13*(1-B228) -> 172318.21 | M15: =M13*(1-B228) -> 310172.78 | N15: =N13*(1-B228) -> 353596.97 | O15: =O13*(1-B228) -> 403100.55 | P15: =P13*(1-B228) -> 459534.62 | Q15: =Q13*(1-B228) -> 523869.47 | R15: =R13*(1-B228) -> 576256.42 | S15: =S13*(1-B228) -> 633882.06 | T15: =T13*(1-B228) -> 697270.27 | U15: =U13*(1-B228) -> 766997.29 | V15: =V13*(1-B228) -> 843697.02
A16: C. FREE CASH FLOW BUILD
A17: (+) D&A ($000s) | B17: =B6*B225 -> 12767.2 | C17: =C6*B225 -> 14937.624 | D17: =D6*B225 -> 18223.901 | E17: =E6*B225 -> 22779.877 | F17: =F6*B225 -> 29158.242 | G17: =G6*B225 -> 36447.803 | H17: =H6*B225 -> 43737.363 | I17: =I6*B225 -> 52484.836 | J17: =J6*B225 -> 62981.803 | K17: =K6*B225 -> 75578.163 | L17: =L6*B225 -> 90693.796 | M17: =M6*B225 -> 103390.93 | N17: =N6*B225 -> 117865.66 | O17: =O6*B225 -> 134366.85 | P17: =P6*B225 -> 153178.21 | Q17: =Q6*B225 -> 174623.16 | R17: =R6*B225 -> 192085.47 | S17: =S6*B225 -> 211294.02 | T17: =T6*B225 -> 232423.42 | U17: =U6*B225 -> 255665.76 | V17: =V6*B225 -> 281232.34
A18: (−) CapEx + Cap. Software ($000s) | B18: =B6*B226 -> 3830.16 | C18: =C6*B226 -> 4481.2872 | D18: =D6*B226 -> 5467.1704 | E18: =E6*B226 -> 6833.963 | F18: =F6*B226 -> 8747.4726 | G18: =G6*B226 -> 10934.341 | H18: =H6*B226 -> 13121.209 | I18: =I6*B226 -> 15745.451 | J18: =J6*B226 -> 18894.541 | K18: =K6*B226 -> 22673.449 | L18: =L6*B226 -> 27208.139 | M18: =M6*B226 -> 31017.278 | N18: =N6*B226 -> 35359.697 | O18: =O6*B226 -> 40310.055 | P18: =P6*B226 -> 45953.462 | Q18: =Q6*B226 -> 52386.947 | R18: =R6*B226 -> 57625.642 | S18: =S6*B226 -> 63388.206 | T18: =T6*B226 -> 69727.027 | U18: =U6*B226 -> 76699.729 | V18: =V6*B226 -> 84369.702
A19: (−) Change in NWC ($000s) | B19: =0 -> 0 | C19: =(C6-B6)*B227 -> 868.1696 | D19: =(D6-C6)*B227 -> 1314.5109 | E19: =(E6-D6)*B227 -> 1822.3901 | F19: =(F6-E6)*B227 -> 2551.3462 | G19: =(G6-F6)*B227 -> 2915.8242 | H19: =(H6-G6)*B227 -> 2915.8242 | I19: =(I6-H6)*B227 -> 3498.989 | J19: =(J6-I6)*B227 -> 4198.7869 | K19: =(K6-J6)*B227 -> 5038.5442 | L19: =(L6-K6)*B227 -> 6046.2531 | M19: =(M6-L6)*B227 -> 5078.8526 | N19: =(N6-M6)*B227 -> 5789.8919 | O19: =(O6-N6)*B227 -> 6600.4768 | P19: =(P6-O6)*B227 -> 7524.5436 | Q19: =(Q6-P6)*B227 -> 8577.9797 | R19: =(R6-Q6)*B227 -> 6984.9263 | S19: =(S6-R6)*B227 -> 7683.4189 | T19: =(T6-S6)*B227 -> 8451.7608 | U19: =(U6-T6)*B227 -> 9296.9369 | V19: =(V6-U6)*B227 -> 10226.631
A20: UNLEVERED FCF ($000s) | B20: =B15+B17-B18-B19 -> 67237867 | C20: =C15+C17-C18-C19 -> -41199.754 | D20: =D15+D17-D18-D19 -> -23183.192 | E20: =E15+E17-E18-E19 -> 455.59753 | F20: =F15+F17-F18-F19 -> 32438.544 | G20: =G15+G17-G18-G19 -> 69979.781 | H20: =H15+H17-H18-H19 -> 110801.32 | I20: =I15+I17-I18-I19 -> 132961.58 | ... V20: =V15+V17-V18-V19 -> 1030333
A21: UFCF Margin % | B21: =IF(B6<>0,B20/B6,0) -> 526.64536 | C21: =IF(C6<>0,C20/C6,0) -> -0.27581197 | D21: =IF(D6<>0,D20/D6,0) -> -0.12721311 | E21: =IF(E6<>0,E20/E6,0) -> 0.002 | F21: =IF(F6<>0,F20/F6,0) -> 0.11125 | G21: =IF(G6<>0,G20/G6,0) -> 0.192 | H21: =IF(H6<>0,H20/H6,0) -> 0.25333333 | I21: =IF(I6<>0,I20/I6,0) -> 0.25333333 | ... V21: =IF(V6<>0,V20/V6,0) -> 0.36636364
A22: D. WACC RE-RATING ← THE SINGLE BIGGEST LEVER | Base=17.2% → $10 Scenario=~10%
A23: WACC (from assumption block below) | B23: =B238 -> 0.09547 | C23: =B238 -> 0.09547 | D23: =B238 -> 0.09547 | E23: =B238 -> 0.09547 | F23: =B238 -> 0.09547 | G23: =B238 -> 0.09547 | H23: =B238 -> 0.09547 | I23: =B238 -> 0.09547 | J23: =B238 -> 0.09547 | K23: =B238 -> 0.09547 | L23: =B238 -> 0.09547 | M23: =B238 -> 0.09547 | N23: =B238 -> 0.09547 | O23: =B238 -> 0.09547 | P23: =B238 -> 0.09547 | Q23: =B238 -> 0.09547 | R23: =B238 -> 0.09547 | S23: =B238 -> 0.09547 | T23: =B238 -> 0.09547 | U23: =B238 -> 0.09547 | V23: =B238 -> 0.09547 | W23: =B238 -> 0.09547
A24: Discount Period (Mid-Year) | B24: — | C24: =1-0.5 -> 0.5 | D24: =2-0.5 -> 1.5 | E24: =3-0.5 -> 2.5 | F24: =4-0.5 -> 3.5 | G24: =5-0.5 -> 4.5 | H24: =6-0.5 -> 5.5 | I24: =7-0.5 -> 6.5 | J24: =8-0.5 -> 7.5 | K24: =9-0.5 -> 8.5 | L24: =10-0.5 -> 9.5 | M24: =11-0.5 -> 10.5 | N24: =12-0.5 -> 11.5 | O24: =13-0.5 -> 12.5 | P24: =14-0.5 -> 13.5 | Q24: =15-0.5 -> 14.5 | R24: =16-0.5 -> 15.5 | S24: =17-0.5 -> 16.5 | T24: =18-0.5 -> 17.5 | U24: =19-0.5 -> 18.5 | V24: =20-0.5 -> 19.5
A25: Discount Factor | B25: — | C25: =1/(1+C23)^C24 -> 0.95543194 | D25: =1/(1+D23)^D24 -> 0.87216623 | E25: =1/(1+E23)^E24 -> 0.79615711 | F25: =1/(1+F23)^F24 -> 0.72677217 | G25: =1/(1+G23)^G24 -> 0.66343412 | H25: =1/(1+H23)^H24 -> 0.60561596 | I25: =1/(1+I23)^I24 -> 0.55283665 | J25: =1/(1+J23)^J24 -> 0.50465704 | ... V25: =1/(1+V23)^V24 -> 0.16896256
A26: PV of UFCF ($000s) | B26: — | C26: =C20*C25 -> -39363.561 | D26: =D20*D25 -> -20219.598 | E26: =E20*E25 -> 362.72721 | F26: =F20*F25 -> 23575.431 | G26: =G20*G25 -> 46426.974 | H26: =H20*H25 -> 67103.048 | I26: =I20*I25 -> 73506.036 | J26: =J20*J25 -> 80519.999 | ... V26: =V20*V25 -> 174087.7
A27: Sum of PV (UFCF) — Years 1–20 ($000s) | B27: =SUM(C26:V26) -> 2065887.8
A28: E. TERMINAL VALUE
A29: Terminal Growth Rate | B29: =B239 -> 0.04
A30: Terminal Value — Gordon Growth (undiscounted, $000s) | B30: =IF(B238>B29,V20*(1+B29)/(B238-B29),0) -> 19317583
A31: PV of Terminal Value ($000s) | B31: =B30/(1+B238)^20 -> 3118480.4
A32: Terminal Value as % of EV | B32: =IF((B27+B31)<>0,B31/(B27+B31),0) -> 0.601516
A33: F. ENTERPRISE VALUE → EQUITY VALUE → IMPLIED SHARE PRICE
A34: Enterprise Value ($000s) | B34: =B27+B31 -> 5184368.2
A35: (+) Net Cash — $444M floor ($000s) | B35: =MAX(0,Assumptions!C27-Assumptions!C32) -> 443868 | C35: ← This alone is worth $0.93/share; protects downside
A36: (−) Net Debt ($000s) | B36: =MAX(0,Assumptions!C32-Assumptions!C27) -> 0
A37: Equity Value ($000s) | B37: =B34+B35-B36 -> 5628236.2
A38: Diluted Shares (Post-Jan-2026) | B38: =Assumptions!C34 -> 475055655
A39: ★ IMPLIED SHARE PRICE ($) | B39: =IF(B38>0,B37*1000/B38,0) -> 11.84753
A41: G. WHAT DRIVES THE DIFFERENCE? | Base Case ($1.18) vs $10 Re-Rating Scenario
...
