Workbook

Sheet Assumptions
A1: RGTI — DCF Model Assumptions
A2: All dollar inputs in $thousands | Blue = input | Black = formula | Yellow = key assumption
A4: A. HISTORICAL FINANCIAL DATA (Source: RGTI 10-K FY2025, SEC EDGAR CIK 0001838359)
A5: Line Item | B5: FY2023 | C5: FY2024 | D5: FY2025 | E5: Notes
A6: Revenue | B6: 12008 | C6: 10790 | D6: 7088 | E6: EDGAR RevenueFromContractWithCustomerIncludingAssessedTax
A7: Cost of Revenue | B7: 2800 | C7: 5093 | D7: 5024 | E7: EDGAR CostOfRevenue
A8: Gross Profit ($000s) | B8: =B6-B7 | C8: =C6-C7 | D8: =D6-D7 | E8: Formula: Revenue − CoR
A9: Gross Margin % | B9: =B8/B6 | C9: =C8/C6 | D9: =D8/D6 | E9: Formula
A10: SG&A | B10: 27744 | C10: 24457 | D10: 25379 | E10: EDGAR GeneralAndAdministrativeExpense
A11: R&D | B11: 52768 | C11: 49750 | D11: 61345 | E11: EDGAR ResearchAndDevelopmentExpense
A12: EBIT (Operating Loss) | B12: -72295 | C12: -68510 | D12: -84660 | E12: EDGAR OperatingIncomeLoss
A13: D&A | B13: 7400 | C13: 6900 | D13: 8100 | E13: EDGAR DepreciationDepletionAndAmortization (cash-flow stmt)
A14: Stock-Based Comp | B14: 12409 | C14: 13069 | D14: 17605 | E14: EDGAR AllocatedShareBasedCompensationExpense
A15: CapEx (PP&E) | B15: 9059 | C15: 11098 | D15: 18676 | E15: EDGAR PaymentsToAcquirePropertyPlantAndEquipment
A16: Capitalized Software | B16: 0 | C16: 0 | D16: 0 | E16: Source: EDGAR
A17: Interest Expense | B17: 5779 | C17: 0 | D17: 0 | E17: EDGAR InterestExpense (0 in FY2024/25 — debt fully retired)
A18: Interest Income | B18: 0 | C18: 0 | D18: 0 | E18: Not separately tagged in XBRL
A19: Net Loss | B19: -75107 | C19: -200988 | D19: -216210 | E19: EDGAR NetIncomeLoss
A22: A2. BALANCE SHEET SNAPSHOT (Source: RGTI 10-K FY2025, SEC EDGAR CIK 0001838359)
A23: Line Item | B23: FY2024 | C23: FY2025 | E23: Notes
A24: Cash & Equivalents | B24: 67674 | C24: 44851 | E24: EDGAR Cash
A25: AFS Investments (Current) | B25: 0 | C25: 0 | E25: EDGAR / 0 if none
A26: AFS Investments (Non-Current) | B26: 0 | C26: 0 | E26: EDGAR / 0 if none
A27: Total Liquidity | B27: =B24+B25+B26 | C27: =C24+C25+C26 | E27: Formula: Cash + AFS
A28: Accounts Receivable | B28: 2427 | C28: 2551 | E28: EDGAR AR
A29: Goodwill | B29: 0 | C29: 0 | E29: EDGAR Goodwill
A30: Intangibles, net | B30: 0 | C30: 0 | E30: EDGAR Intangibles
A31: Total Debt (Gross Principal) | B31: 0 | C31: 0 | E31: EDGAR Debt
A32: Post-FY2025 Debt | B32: =B31 | C32: 0 | E32: Debt-free as of FY2024; term loan fully retired
A33: Shares Outstanding | B33: 184666000 | C33: 309763000 | E33: EDGAR diluted shares
A34: Shares Used in Bridge | B34: =B33 | C34: 309763000 | E34: FY2025 diluted wtd-avg (significant ongoing dilution expected)
A35: Federal NOL Carryforward ($K) | C35: 131826 | E35: EDGAR DeferredTaxAssetsGross FY2025 ($K proxy for NOL)
A38: B. REVENUE GROWTH ASSUMPTIONS (Yellow = key input)
A39: Assumption | B39: Base Case | C39: Bull Case | D39: Bear Case | E39: Notes
A40: FY2026 Revenue Growth Rate | B40: 0.5 | C40: 1 | D40: -0.1 | E40: Revenue declining in FY2025; stabilisation + first commercial ramp
A41: FY2027 Revenue Growth Rate | B41: 0.8 | C41: 2 | D41: 0.1 | E41: Quantum advantage demonstrations driving enterprise pilots
A42: FY2028 Revenue Growth Rate | B42: 1.2 | C42: 2.5 | D42: 0.2 | E42: Multi-qubit systems reaching commercial-grade fidelity
A43: FY2029 Revenue Growth Rate | B43: 1 | C43: 2 | D43: 0.3 | E43: Hyperscaler + pharma / finance contract wins
A44: FY2030 Revenue Growth Rate | B44: 0.8 | C44: 1.5 | D44: 0.25 | E44: TAM penetration; Rigetti platform-as-a-service scaling
A45: FY2031–2035 Revenue Growth Rate | B45: 0.6 | C45: 1 | D45: 0.18 | E45: Quantum-classical hybrid workloads mainstream
...

Sheet DCF Model
A1: RGTI — 20-Year Unlevered Free Cash Flow DCF Model
A2: =IF(Assumptions!B50=1,"▶ ACTIVE: BASE CASE",IF(Assumptions!B50=2,"▶ ACTIVE: BULL CASE","▶ ACTIVE: BEAR CASE"))
A3: Year | B3: FY2025 (Actual) | C3: 2026 | D3: 2027 | E3: 2028 | F3: 2029 | G3: 2030 | H3: 2031 | I3: 2032 | J3: 2033 | K3: 2034 | L3: 2035 | M3: 2036 | N3: 2037 | O3: 2038 | P3: 2039 | Q3: 2040 | R3: 2041 | S3: 2042 | T3: 2043 | U3: 2044 | V3: 2045
A4: A. REVENUE PROJECTION
A5: Revenue Growth Rate (Active Scenario) | B5: — | C5: =CHOOSE(Assumptions!B50,Assumptions!B40,Assumptions!C40,Assumptions!D40) | D5: =CHOOSE(Assumptions!B50,Assumptions!B41,Assumptions!C41,Assumptions!D41) | E5: =CHOOSE(Assumptions!B50,Assumptions!B42,Assumptions!C42,Assumptions!D42) | F5: =CHOOSE(Assumptions!B50,Assumptions!B43,Assumptions!C43,Assumptions!D43) | G5: =CHOOSE(Assumptions!B50,Assumptions!B44,Assumptions!C44,Assumptions!D44) | H5: =CHOOSE(Assumptions!B50,Assumptions!B45,Assumptions!C45,Assumptions!D45) | I5: =CHOOSE(Assumptions!B50,Assumptions!B45,Assumptions!C45,Assumptions!D45) | J5: =CHOOSE(Assumptions!B50,Assumptions!B45,Assumptions!C45,Assumptions!D45) | K5: =CHOOSE(Assumptions!B50,Assumptions!B45,Assumptions!C45,Assumptions!D45) | L5: =CHOOSE(Assumptions!B50,Assumptions!B45,Assumptions!C45,Assumptions!D45) | M5: =CHOOSE(Assumptions!B50,Assumptions!B46,Assumptions!C46,Assumptions!D46) | N5: =CHOOSE(Assumptions!B50,Assumptions!B46,Assumptions!C46,Assumptions!D46) | O5: =CHOOSE(Assumptions!B50,Assumptions!B46,Assumptions!C46,Assumptions!D46) | P5: =CHOOSE(Assumptions!B50,Assumptions!B46,Assumptions!C46,Assumptions!D46) | Q5: =CHOOSE(Assumptions!B50,Assumptions!B46,Assumptions!C46,Assumptions!D46) | R5: =CHOOSE(Assumptions!B50,Assumptions!B47,Assumptions!C47,Assumptions!D47) | S5: =CHOOSE(Assumptions!B50,Assumptions!B47,Assumptions!C47,Assumptions!D47) | T5: =CHOOSE(Assumptions!B50,Assumptions!B47,Assumptions!C47,Assumptions!D47) | U5: =CHOOSE(Assumptions!B50,Assumptions!B47,Assumptions!C47,Assumptions!D47) | V5: =CHOOSE(Assumptions!B50,Assumptions!B47,Assumptions!C47,Assumptions!D47)
A6: Revenue ($000s) | B6: =Assumptions!D6 | C6: =B6*(1+C5) | D6: =C6*(1+D5) | E6: =D6*(1+E5) | F6: =E6*(1+F5) | G6: =F6*(1+G5) | H6: =G6*(1+H5) | I6: =H6*(1+I5) | J6: =I6*(1+J5) | ... V6: =U6*(1+V5)
A7: B. INCOME STATEMENT PROJECTION
A8: Gross Margin % | B8: =Assumptions!D9 | C8: =CHOOSE(Assumptions!B50,Assumptions!B54,Assumptions!C54,Assumptions!D54) | D8: =CHOOSE(Assumptions!B50,Assumptions!B55,Assumptions!C55,Assumptions!D55) | E8: =CHOOSE(Assumptions!B50,Assumptions!B56,Assumptions!C56,Assumptions!D56) | F8: =CHOOSE(Assumptions!B50,Assumptions!B57,Assumptions!C57,Assumptions!D57) | G8: =CHOOSE(Assumptions!B50,Assumptions!B58,Assumptions!C58,Assumptions!D58) | H8: =CHOOSE(Assumptions!B50,Assumptions!B59,Assumptions!C59,Assumptions!D59) | I8: =CHOOSE(Assumptions!B50,Assumptions!B59,Assumptions!C59,Assumptions!D59) | J8: =CHOOSE(Assumptions!B50,Assumptions!B59,Assumptions!C59,Assumptions!D59) | K8: =CHOOSE(Assumptions!B50,Assumptions!B59,Assumptions!C59,Assumptions!D59) | L8: =CHOOSE(Assumptions!B50,Assumptions!B59,Assumptions!C59,Assumptions!D59) | M8: =CHOOSE(Assumptions!B50,Assumptions!B60,Assumptions!C60,Assumptions!D60) | N8: =CHOOSE(Assumptions!B50,Assumptions!B60,Assumptions!C60,Assumptions!D60) | O8: =CHOOSE(Assumptions!B50,Assumptions!B60,Assumptions!C60,Assumptions!D60) | P8: =CHOOSE(Assumptions!B50,Assumptions!B60,Assumptions!C60,Assumptions!D60) | Q8: =CHOOSE(Assumptions!B50,Assumptions!B60,Assumptions!C60,Assumptions!D60) | R8: =CHOOSE(Assumptions!B50,Assumptions!B60,Assumptions!C60,Assumptions!D60) | S8: =CHOOSE(Assumptions!B50,Assumptions!B60,Assumptions!C60,Assumptions!D60) | T8: =CHOOSE(Assumptions!B50,Assumptions!B60,Assumptions!C60,Assumptions!D60) | U8: =CHOOSE(Assumptions!B50,Assumptions!B60,Assumptions!C60,Assumptions!D60) | V8: =CHOOSE(Assumptions!B50,Assumptions!B60,Assumptions!C60,Assumptions!D60)
A9: Gross Profit ($000s) | B9: =Assumptions!D8 | C9: =C6*C8 | D9: =D6*D8 | E9: =E6*E8 | F9: =F6*F8 | G9: =G6*G8 | H9: =H6*H8 | I9: =I6*I8 | J9: =J6*J8 | ... V9: =V6*V8
A10: SG&A as % Revenue | B10: =Assumptions!D10/Assumptions!D6 | C10: =CHOOSE(Assumptions!B50,Assumptions!B61,Assumptions!C61,Assumptions!D61) | D10: =CHOOSE(Assumptions!B50,Assumptions!B62,Assumptions!C62,Assumptions!D62) | E10: =CHOOSE(Assumptions!B50,Assumptions!B63,Assumptions!C63,Assumptions!D63) | F10: =CHOOSE(Assumptions!B50,Assumptions!B64,Assumptions!C64,Assumptions!D64) | G10: =CHOOSE(Assumptions!B50,Assumptions!B65,Assumptions!C65,Assumptions!D65) | H10: =CHOOSE(Assumptions!B50,Assumptions!B66,Assumptions!C66,Assumptions!D66) | I10: =CHOOSE(Assumptions!B50,Assumptions!B66,Assumptions!C66,Assumptions!D66) | J10: =CHOOSE(Assumptions!B50,Assumptions!B66,Assumptions!C66,Assumptions!D66) | K10: =CHOOSE(Assumptions!B50,Assumptions!B66,Assumptions!C66,Assumptions!D66) | L10: =CHOOSE(Assumptions!B50,Assumptions!B66,Assumptions!C66,Assumptions!D66) | M10: =CHOOSE(Assumptions!B50,Assumptions!B67,Assumptions!C67,Assumptions!D67) | N10: =CHOOSE(Assumptions!B50,Assumptions!B67,Assumptions!C67,Assumptions!D67) | O10: =CHOOSE(Assumptions!B50,Assumptions!B67,Assumptions!C67,Assumptions!D67) | P10: =CHOOSE(Assumptions!B50,Assumptions!B67,Assumptions!C67,Assumptions!D67) | Q10: =CHOOSE(Assumptions!B50,Assumptions!B67,Assumptions!C67,Assumptions!D67) | R10: =CHOOSE(Assumptions!B50,Assumptions!B67,Assumptions!C67,Assumptions!D67) | S10: =CHOOSE(Assumptions!B50,Assumptions!B67,Assumptions!C67,Assumptions!D67) | T10: =CHOOSE(Assumptions!B50,Assumptions!B67,Assumptions!C67,Assumptions!D67) | U10: =CHOOSE(Assumptions!B50,Assumptions!B67,Assumptions!C67,Assumptions!D67) | V10: =CHOOSE(Assumptions!B50,Assumptions!B67,Assumptions!C67,Assumptions!D67)
A11: SG&A ($000s) | B11: =Assumptions!D10 | C11: =C6*C10 | D11: =D6*D10 | E11: =E6*E10 | F11: =F6*F10 | G11: =G6*G10 | H11: =H6*H10 | I11: =I6*I10 | J11: =J6*J10 | ... V11: =V6*V10
A12: R&D as % Revenue | B12: =Assumptions!D11/Assumptions!D6 | C12: =CHOOSE(Assumptions!B50,Assumptions!B68,Assumptions!C68,Assumptions!D68) | D12: =CHOOSE(Assumptions!B50,Assumptions!B68,Assumptions!C68,Assumptions!D68) | E12: =CHOOSE(Assumptions!B50,Assumptions!B68,Assumptions!C68,Assumptions!D68) | F12: =CHOOSE(Assumptions!B50,Assumptions!B68,Assumptions!C68,Assumptions!D68) | G12: =CHOOSE(Assumptions!B50,Assumptions!B68,Assumptions!C68,Assumptions!D68) | H12: =CHOOSE(Assumptions!B50,Assumptions!B68,Assumptions!C68,Assumptions!D68) | I12: =CHOOSE(Assumptions!B50,Assumptions!B68,Assumptions!C68,Assumptions!D68) | J12: =CHOOSE(Assumptions!B50,Assumptions!B68,Assumptions!C68,Assumptions!D68) | K12: =CHOOSE(Assumptions!B50,Assumptions!B68,Assumptions!C68,Assumptions!D68) | L12: =CHOOSE(Assumptions!B50,Assumptions!B68,Assumptions!C68,Assumptions!D68) | M12: =CHOOSE(Assumptions!B50,Assumptions!B68,Assumptions!C68,Assumptions!D68) | N12: =CHOOSE(Assumptions!B50,Assumptions!B68,Assumptions!C68,Assumptions!D68) | O12: =CHOOSE(Assumptions!B50,Assumptions!B68,Assumptions!C68,Assumptions!D68) | P12: =CHOOSE(Assumptions!B50,Assumptions!B68,Assumptions!C68,Assumptions!D68) | Q12: =CHOOSE(Assumptions!B50,Assumptions!B68,Assumptions!C68,Assumptions!D68) | R12: =CHOOSE(Assumptions!B50,Assumptions!B68,Assumptions!C68,Assumptions!D68) | S12: =CHOOSE(Assumptions!B50,Assumptions!B68,Assumptions!C68,Assumptions!D68) | T12: =CHOOSE(Assumptions!B50,Assumptions!B68,Assumptions!C68,Assumptions!D68) | U12: =CHOOSE(Assumptions!B50,Assumptions!B68,Assumptions!C68,Assumptions!D68) | V12: =CHOOSE(Assumptions!B50,Assumptions!B68,Assumptions!C68,Assumptions!D68)
A13: R&D ($000s) | B13: =Assumptions!D11 | C13: =C6*C12 | D13: =D6*D12 | E13: =E6*E12 | F13: =F6*F12 | G13: =G6*G12 | H13: =H6*H12 | I13: =I6*I12 | J13: =J6*J12 | ... V13: =V6*V12
A14: EBIT ($000s) | B14: =Assumptions!D12 | C14: =C9-C11-C13 | D14: =D9-D11-D13 | E14: =E9-E11-E13 | F14: =F9-F11-F13 | G14: =G9-G11-G13 | H14: =H9-H11-H13 | I14: =I9-I11-I13 | J14: =J9-J11-J13 | ... V14: =V9-V11-V13
A15: EBIT Margin % | B15: =Assumptions!D12/Assumptions!D6 | C15: =C14/C6 | D15: =D14/D6 | E15: =E14/E6 | F15: =F14/F6 | G15: =G14/G6 | H15: =H14/H6 | I15: =I14/I6 | J15: =J14/J6 | ... V15: =V14/V6
A16: Cash Tax Rate (Active Scenario) | B16: =0 | C16: =CHOOSE(Assumptions!B50,Assumptions!B73,Assumptions!C73,Assumptions!D73) | D16: =CHOOSE(Assumptions!B50,Assumptions!B73,Assumptions!C73,Assumptions!D73) | E16: =CHOOSE(Assumptions!B50,Assumptions!B73,Assumptions!C73,Assumptions!D73) | F16: =CHOOSE(Assumptions!B50,Assumptions!B73,Assumptions!C73,Assumptions!D73) | G16: =CHOOSE(Assumptions!B50,Assumptions!B73,Assumptions!C73,Assumptions!D73) | H16: =CHOOSE(Assumptions!B50,Assumptions!B73,Assumptions!C73,Assumptions!D73) | I16: =CHOOSE(Assumptions!B50,Assumptions!B73,Assumptions!C73,Assumptions!D73) | J16: =CHOOSE(Assumptions!B50,Assumptions!B73,Assumptions!C73,Assumptions!D73) | K16: =CHOOSE(Assumptions!B50,Assumptions!B73,Assumptions!C73,Assumptions!D73) | L16: =CHOOSE(Assumptions!B50,Assumptions!B73,Assumptions!C73,Assumptions!D73) | M16: =CHOOSE(Assumptions!B50,Assumptions!B73,Assumptions!C73,Assumptions!D73) | N16: =CHOOSE(Assumptions!B50,Assumptions!B73,Assumptions!C73,Assumptions!D73) | O16: =CHOOSE(Assumptions!B50,Assumptions!B73,Assumptions!C73,Assumptions!D73) | P16: =CHOOSE(Assumptions!B50,Assumptions!B73,Assumptions!C73,Assumptions!D73) | Q16: =CHOOSE(Assumptions!B50,Assumptions!B73,Assumptions!C73,Assumptions!D73) | R16: =CHOOSE(Assumptions!B50,Assumptions!B73,Assumptions!C73,Assumptions!D73) | S16: =CHOOSE(Assumptions!B50,Assumptions!B73,Assumptions!C73,Assumptions!D73) | T16: =CHOOSE(Assumptions!B50,Assumptions!B73,Assumptions!C73,Assumptions!D73) | U16: =CHOOSE(Assumptions!B50,Assumptions!B73,Assumptions!C73,Assumptions!D73) | V16: =CHOOSE(Assumptions!B50,Assumptions!B73,Assumptions!C73,Assumptions!D73)
A17: NOPAT = EBIT × (1 − Tax Rate) ($000s) | B17: =B14*(1-B16) | C17: =C14*(1-C16) | D17: =D14*(1-D16) | E17: =E14*(1-E16) | F17: =F14*(1-F16) | G17: =G14*(1-G16) | H17: =H14*(1-H16) | I17: =I14*(1-I16) | ... V17: =V14*(1-V16)
A18: C. UNLEVERED FREE CASH FLOW BUILD
A19: D&A as % Revenue | B19: =Assumptions!D13/Assumptions!D6 | C19: =CHOOSE(Assumptions!B50,Assumptions!B69,Assumptions!C69,Assumptions!D69) | D19: =CHOOSE(Assumptions!B50,Assumptions!B69,Assumptions!C69,Assumptions!D69) | E19: =CHOOSE(Assumptions!B50,Assumptions!B69,Assumptions!C69,Assumptions!D69) | F19: =CHOOSE(Assumptions!B50,Assumptions!B69,Assumptions!C69,Assumptions!D69) | G19: =CHOOSE(Assumptions!B50,Assumptions!B69,Assumptions!C69,Assumptions!D69) | H19: =CHOOSE(Assumptions!B50,Assumptions!B69,Assumptions!C69,Assumptions!D69) | I19: =CHOOSE(Assumptions!B50,Assumptions!B69,Assumptions!C69,Assumptions!D69) | J19: =CHOOSE(Assumptions!B50,Assumptions!B69,Assumptions!C69,Assumptions!D69) | K19: =CHOOSE(Assumptions!B50,Assumptions!B69,Assumptions!C69,Assumptions!D69) | L19: =CHOOSE(Assumptions!B50,Assumptions!B69,Assumptions!C69,Assumptions!D69) | M19: =CHOOSE(Assumptions!B50,Assumptions!B69,Assumptions!C69,Assumptions!D69) | N19: =CHOOSE(Assumptions!B50,Assumptions!B69,Assumptions!C69,Assumptions!D69) | O19: =CHOOSE(Assumptions!B50,Assumptions!B69,Assumptions!C69,Assumptions!D69) | P19: =CHOOSE(Assumptions!B50,Assumptions!B69,Assumptions!C69,Assumptions!D69) | Q19: =CHOOSE(Assumptions!B50,Assumptions!B69,Assumptions!C69,Assumptions!D69) | R19: =CHOOSE(Assumptions!B50,Assumptions!B69,Assumptions!C69,Assumptions!D69) | S19: =CHOOSE(Assumptions!B50,Assumptions!B69,Assumptions!C69,Assumptions!D69) | T19: =CHOOSE(Assumptions!B50,Assumptions!B69,Assumptions!C69,Assumptions!D69) | U19: =CHOOSE(Assumptions!B50,Assumptions!B69,Assumptions!C69,Assumptions!D69) | V19: =CHOOSE(Assumptions!B50,Assumptions!B69,Assumptions!C69,Assumptions!D69)
A20: (+) D&A ($000s) | B20: =Assumptions!D13 | C20: =C6*C19 | D20: =D6*D19 | E20: =E6*E19 | F20: =F6*F19 | G20: =G6*G19 | H20: =H6*H19 | I20: =I6*I19 | J20: =J6*J19 | ... V20: =V6*V19
A21: CapEx as % Revenue | B21: =(Assumptions!D15+Assumptions!D16)/Assumptions!D6 | C21: =CHOOSE(Assumptions!B50,Assumptions!B70,Assumptions!C70,Assumptions!D70) | D21: =CHOOSE(Assumptions!B50,Assumptions!B70,Assumptions!C70,Assumptions!D70) | E21: =CHOOSE(Assumptions!B50,Assumptions!B70,Assumptions!C70,Assumptions!D70) | F21: =CHOOSE(Assumptions!B50,Assumptions!B70,Assumptions!C70,Assumptions!D70) | G21: =CHOOSE(Assumptions!B50,Assumptions!B70,Assumptions!C70,Assumptions!D70) | H21: =CHOOSE(Assumptions!B50,Assumptions!B70,Assumptions!C70,Assumptions!D70) | I21: =CHOOSE(Assumptions!B50,Assumptions!B70,Assumptions!C70,Assumptions!D70) | J21: =CHOOSE(Assumptions!B50,Assumptions!B70,Assumptions!C70,Assumptions!D70) | K21: =CHOOSE(Assumptions!B50,Assumptions!B70,Assumptions!C70,Assumptions!D70) | L21: =CHOOSE(Assumptions!B50,Assumptions!B70,Assumptions!C70,Assumptions!D70) | M21: =CHOOSE(Assumptions!B50,Assumptions!B70,Assumptions!C70,Assumptions!D70) | N21: =CHOOSE(Assumptions!B50,Assumptions!B70,Assumptions!C70,Assumptions!D70) | O21: =CHOOSE(Assumptions!B50,Assumptions!B70,Assumptions!C70,Assumptions!D70) | P21: =CHOOSE(Assumptions!B50,Assumptions!B70,Assumptions!C70,Assumptions!D70) | Q21: =CHOOSE(Assumptions!B50,Assumptions!B70,Assumptions!C70,Assumptions!D70) | R21: =CHOOSE(Assumptions!B50,Assumptions!B70,Assumptions!C70,Assumptions!D70) | S21: =CHOOSE(Assumptions!B50,Assumptions!B70,Assumptions!C70,Assumptions!D70) | T21: =CHOOSE(Assumptions!B50,Assumptions!B70,Assumptions!C70,Assumptions!D70) | U21: =CHOOSE(Assumptions!B50,Assumptions!B70,Assumptions!C70,Assumptions!D70) | V21: =CHOOSE(Assumptions!B50,Assumptions!B70,Assumptions!C70,Assumptions!D70)
A22: (−) CapEx + Capitalized Software ($000s) | B22: =Assumptions!D15+Assumptions!D16 | C22: =C6*C21 | D22: =D6*D21 | E22: =E6*E21 | F22: =F6*F21 | G22: =G6*G21 | H22: =H6*H21 | I22: =I6*I21 | J22: =J6*J21 | ... V22: =V6*V21
A23: Δ NWC as % Revenue Change | B23: =0 | C23: =CHOOSE(Assumptions!B50,Assumptions!B72,Assumptions!C72,Assumptions!D72) | D23: =CHOOSE(Assumptions!B50,Assumptions!B72,Assumptions!C72,Assumptions!D72) | E23: =CHOOSE(Assumptions!B50,Assumptions!B72,Assumptions!C72,Assumptions!D72) | F23: =CHOOSE(Assumptions!B50,Assumptions!B72,Assumptions!C72,Assumptions!D72) | G23: =CHOOSE(Assumptions!B50,Assumptions!B72,Assumptions!C72,Assumptions!D72) | H23: =CHOOSE(Assumptions!B50,Assumptions!B72,Assumptions!C72,Assumptions!D72) | I23: =CHOOSE(Assumptions!B50,Assumptions!B72,Assumptions!C72,Assumptions!D72) | J23: =CHOOSE(Assumptions!B50,Assumptions!B72,Assumptions!C72,Assumptions!D72) | K23: =CHOOSE(Assumptions!B50,Assumptions!B72,Assumptions!C72,Assumptions!D72) | L23: =CHOOSE(Assumptions!B50,Assumptions!B72,Assumptions!C72,Assumptions!D72) | M23: =CHOOSE(Assumptions!B50,Assumptions!B72,Assumptions!C72,Assumptions!D72) | N23: =CHOOSE(Assumptions!B50,Assumptions!B72,Assumptions!C72,Assumptions!D72) | O23: =CHOOSE(Assumptions!B50,Assumptions!B72,Assumptions!C72,Assumptions!D72) | P23: =CHOOSE(Assumptions!B50,Assumptions!B72,Assumptions!C72,Assumptions!D72) | Q23: =CHOOSE(Assumptions!B50,Assumptions!B72,Assumptions!C72,Assumptions!D72) | R23: =CHOOSE(Assumptions!B50,Assumptions!B72,Assumptions!C72,Assumptions!D72) | S23: =CHOOSE(Assumptions!B50,Assumptions!B72,Assumptions!C72,Assumptions!D72) | T23: =CHOOSE(Assumptions!B50,Assumptions!B72,Assumptions!C72,Assumptions!D72) | U23: =CHOOSE(Assumptions!B50,Assumptions!B72,Assumptions!C72,Assumptions!D72) | V23: =CHOOSE(Assumptions!B50,Assumptions!B72,Assumptions!C72,Assumptions!D72)
A24: (−) Change in NWC ($000s) | B24: =0 | C24: =(C6-B6)*C23 | D24: =(D6-C6)*D23 | E24: =(E6-D6)*E23 | F24: =(F6-E6)*F23 | G24: =(G6-F6)*G23 | H24: =(H6-G6)*H23 | I24: =(I6-H6)*I23 | J24: =(J6-I6)*J23 | ... V24: =(V6-U6)*V23
A25: UNLEVERED FCF ($000s) | B25: =B17+B20-B22-B24 | C25: =C17+C20-C22-C24 | D25: =D17+D20-D22-D24 | E25: =E17+E20-E22-E24 | F25: =F17+F20-F22-F24 | G25: =G17+G20-G22-G24 | H25: =H17+H20-H22-H24 | I25: =I17+I20-I22-I24 | ... V25: =V17+V20-V22-V24
A26: UFCF Margin % | B26: =IF(B6<>0,B25/B6,0) | C26: =IF(C6<>0,C25/C6,0) | D26: =IF(D6<>0,D25/D6,0) | E26: =IF(E6<>0,E25/E6,0) | F26: =IF(F6<>0,F25/F6,0) | G26: =IF(G6<>0,G25/G6,0) | H26: =IF(H6<>0,H25/H6,0) | I26: =IF(I6<>0,I25/I6,0) | ... V26: =IF(V6<>0,V25/V6,0)
A27: D. DISCOUNTING (Mid-Year Convention)
A28: WACC (Active Scenario) | B28: =CHOOSE(Assumptions!B50,Assumptions!B87,Assumptions!C87,Assumptions!D87) | C28: =CHOOSE(Assumptions!B50,Assumptions!B87,Assumptions!C87,Assumptions!D87) | D28: =CHOOSE(Assumptions!B50,Assumptions!B87,Assumptions!C87,Assumptions!D87) | E28: =CHOOSE(Assumptions!B50,Assumptions!B87,Assumptions!C87,Assumptions!D87) | F28: =CHOOSE(Assumptions!B50,Assumptions!B87,Assumptions!C87,Assumptions!D87) | G28: =CHOOSE(Assumptions!B50,Assumptions!B87,Assumptions!C87,Assumptions!D87) | H28: =CHOOSE(Assumptions!B50,Assumptions!B87,Assumptions!C87,Assumptions!D87) | I28: =CHOOSE(Assumptions!B50,Assumptions!B87,Assumptions!C87,Assumptions!D87) | J28: =CHOOSE(Assumptions!B50,Assumptions!B87,Assumptions!C87,Assumptions!D87) | K28: =CHOOSE(Assumptions!B50,Assumptions!B87,Assumptions!C87,Assumptions!D87) | L28: =CHOOSE(Assumptions!B50,Assumptions!B87,Assumptions!C87,Assumptions!D87) | M28: =CHOOSE(Assumptions!B50,Assumptions!B87,Assumptions!C87,Assumptions!D87) | N28: =CHOOSE(Assumptions!B50,Assumptions!B87,Assumptions!C87,Assumptions!D87) | O28: =CHOOSE(Assumptions!B50,Assumptions!B87,Assumptions!C87,Assumptions!D87) | P28: =CHOOSE(Assumptions!B50,Assumptions!B87,Assumptions!C87,Assumptions!D87) | Q28: =CHOOSE(Assumptions!B50,Assumptions!B87,Assumptions!C87,Assumptions!D87) | R28: =CHOOSE(Assumptions!B50,Assumptions!B87,Assumptions!C87,Assumptions!D87) | S28: =CHOOSE(Assumptions!B50,Assumptions!B87,Assumptions!C87,Assumptions!D87) | T28: =CHOOSE(Assumptions!B50,Assumptions!B87,Assumptions!C87,Assumptions!D87) | U28: =CHOOSE(Assumptions!B50,Assumptions!B87,Assumptions!C87,Assumptions!D87) | V28: =CHOOSE(Assumptions!B50,Assumptions!B87,Assumptions!C87,Assumptions!D87)
A29: Discount Period (Mid-Year) | B29: — | C29: =1-0.5 | D29: =2-0.5 | E29: =3-0.5 | F29: =4-0.5 | G29: =5-0.5 | H29: =6-0.5 | I29: =7-0.5 | J29: =8-0.5 | K29: =9-0.5 | L29: =10-0.5 | M29: =11-0.5 | N29: =12-0.5 | O29: =13-0.5 | P29: =14-0.5 | Q29: =15-0.5 | R29: =16-0.5 | S29: =17-0.5 | T29: =18-0.5 | U29: =19-0.5 | V29: =20-0.5
A30: Discount Factor | B30: — | C30: =1/(1+C28)^C29 | D30: =1/(1+D28)^D29 | E30: =1/(1+E28)^E29 | F30: =1/(1+F28)^F29 | G30: =1/(1+G28)^G29 | H30: =1/(1+H28)^H29 | I30: =1/(1+I28)^I29 | J30: =1/(1+J28)^J29 | ... V30: =1/(1+V28)^V29
A31: PV of UFCF ($000s) | B31: — | C31: =C25*C30 | D31: =D25*D30 | E31: =E25*E30 | F31: =F25*F30 | G31: =G25*G30 | H31: =H25*H30 | I31: =I25*I30 | J31: =J25*J30 | ... V31: =V25*V30
A32: Sum of PV (UFCF) — Years 1–20 ($000s) | B32: =SUM(C31:V31)
A33: E. TERMINAL VALUE (Gordon Growth Model — Primary)
A34: Year 20 UFCF ($000s) | B34: =V25
A35: Terminal Growth Rate (Active Scenario) | B35: =CHOOSE(Assumptions!B50,Assumptions!B92,Assumptions!C92,Assumptions!D92)
A36: WACC (Active Scenario) | B36: =CHOOSE(Assumptions!B50,Assumptions!B87,Assumptions!C87,Assumptions!D87)
A37: Terminal Value (undiscounted) ($000s) | B37: =B34*(1+B35)/(B36-B35)
A38: Terminal Value Discount Factor (Year 20) | B38: =1/(1+V28)^20
A39: PV of Terminal Value ($000s) | B39: =B37*B38
A40: Terminal Value as % of Total Enterprise Value | B40: =B39/(B32+B39)
...
